Workbook

Sheet ilustração
A1: RETRANCA | B1: STATUS | C1: CATEGORIA | D1: LOCALIZAÇÃO | E1: PÁGINA | F1: VOLUME | G1: UNIDADE | H1: CAPÍTULO ou SEÇÃO | I1: TIPO | J1: NOME DA OBRA PARA RESGATE | K1: PÁGINA PARA RESGATE | L1: VOLUME PARA RESGATE | M1: VERSÃO PARA RESGATE | N1: PROPRIEDADE | O1: DESCRIÇÃO DA IMAGEM | P1: OBSERVAÇÃO DO EDITORIAL/NÚCLEO | Q1: LOTE | R1: DATA DE LIBERAÇÃO DO LOTE PARA ARTE | S1: DATA DE ENVIO DO PEDIDO | T1: DATA DO RECEBIMENTO DO RAFE | U1: DATA DE RETORNO DO RAFE PARA ILUSTRADOR | V1: DATA DE RECEBIMENTO DA FINALIZADA | W1: SIGLA | X1: ILUSTRADOR CRIAÇÃO | Y1: ILUSTRADOR AJUSTES | Z1: CRÉDITOS (A e B) | AA1: CLASSIFICAÇÃO | AB1: OBSERVAÇÃO DA ARTE | AC1: OBSERVAÇÃO DE PAGAMENTO | AD1: PROJETO
A2: i0102_1p011chg_g27_e001 | B2: APLICADA | C2: ILUSTRAÇÃO | D2: MIOLO | E2: 18 | F2: 1 | G2: 1 | I2: RESGATE | O2: Resgatar ilustração de menino com balão de pensamento, no balão tem um martelo, uma pera e 3 pontos de interrogação. Veio do 1NPI_G23_LT_MDN, P. 14, código antigo: i0242id_1npg_g23_mdn | W2: id | X2: =IF(Tabela2[[#This Row],[SIGLA]]="","",VLOOKUP(Tabela2[[#This Row],[SIGLA]],créditos_base!B:C,2,0)) -> REINALDO ROSA/ARQUIVO DA EDITORA | Z2: =Tabela2[[#This Row],[ILUSTRADOR CRIAÇÃO]] -> REINALDO ROSA/ARQUIVO DA EDITORA | AD2: ="EF1 E001 HGC" -> EF1 E001 HGC
A3: if0103_1p011chg_g27_e001 | B3: APLICADA | C3: ILUSTRAÇÃO | D3: MIOLO | E3: 20 | F3: 1 | G3: 1 | I3: AJUSTE | O3: Ilustração com foto da professora na sala de aula com os alunos, apresentando as partes do corpo de um menino página 12, g23_mdn_lt_1npc, código antigo i0206ly_1pmc_g19_mdn_ef Vem do 1npc_g23_mdn p. 12. Ajuste: inserir um aparelho auditivo no menino da esquerda, parte inferior da ilustração | Q3: 1 | R3: 45740 | S3: 45740 | V3: 45772 | W3: ly | X3: =IF(Tabela2[[#This Row],[SIGLA]]="","",VLOOKUP(Tabela2[[#This Row],[SIGLA]],créditos_base!B:C,2,0)) -> LISLLEY GOMES FEIGE/ARQUIVO DA EDITORA | Y3: Felipe Grigoli | Z3: =Tabela2[[#This Row],[ILUSTRADOR CRIAÇÃO]] -> LISLLEY GOMES FEIGE/ARQUIVO DA EDITORA | AA3: 13 | AB3: Ajuste Simples | AC3: FINALIZADO | AD3: ="EF1 E001 HGC" -> EF1 E001 HGC
A4: if0104_1p011chg_g27_e001 | B4: APLICADA | C4: ILUSTRAÇÃO | D4: MIOLO | E4: 21 | F4: 1 | G4: 1 | I4: RESGATE | O4: Resgatar ilustração com foto da professora em pé na sala de aula, apresentando as partes do corpo de um menino, g23_mdn_lt_1npc, código antigo i0207ly_1pmc_g19_mdn_ef. Vem do 1 NPC_G23_MDN_LT, página 13 | W4: ly | X4: =IF(Tabela2[[#This Row],[SIGLA]]="","",VLOOKUP(Tabela2[[#This Row],[SIGLA]],créditos_base!B:C,2,0)) -> LISLLEY GOMES FEIGE/ARQUIVO DA EDITORA | Z4: =Tabela2[[#This Row],[ILUSTRADOR CRIAÇÃO]] -> LISLLEY GOMES FEIGE/ARQUIVO DA EDITORA | AD4: ="EF1 E001 HGC" -> EF1 E001 HGC
A5: i0105_1p011chg_g27_e001 | B5: APLICADA | C5: ILUSTRAÇÃO | D5: MIOLO | E5: 22 | F5: 1 | G5: 1 | I5: RESGATE | O5: Resgatar ilustração do boné. Vem do 1 NPC G23_MDN_LT página 14, g23_mdn_lt_1npc, código antigo i0208ec_1pmc_g19_mdn | W5: ec | X5: =IF(Tabela2[[#This Row],[SIGLA]]="","",VLOOKUP(Tabela2[[#This Row],[SIGLA]],créditos_base!B:C,2,0)) -> MÁRCIO GUERRA/ARQUIVO DA EDITORA | Z5: =Tabela2[[#This Row],[ILUSTRADOR CRIAÇÃO]] -> MÁRCIO GUERRA/ARQUIVO DA EDITORA | AD5: ="EF1 E001 HGC" -> EF1 E001 HGC
A6: i0106_1p011chg_g27_e001 | B6: APLICADA | C6: ILUSTRAÇÃO | D6: MIOLO | E6: 22 | F6: 1 | G6: 1 | I6: RESGATE | O6: Resgatar ilustração de camiseta. Vem do 1 NPC G23_MDN_LT página 14, g23_mdn_lt_1npc, código antigo i0209ec_1pmc_g19_mdn | W6: ec | X6: =IF(Tabela2[[#This Row],[SIGLA]]="","",VLOOKUP(Tabela2[[#This Row],[SIGLA]],créditos_base!B:C,2,0)) -> MÁRCIO GUERRA/ARQUIVO DA EDITORA | Z6: =Tabela2[[#This Row],[ILUSTRADOR CRIAÇÃO]] -> MÁRCIO GUERRA/ARQUIVO DA EDITORA | AD6: ="EF1 E001 HGC" -> EF1 E001 HGC
A7: i0107_1p011chg_g27_e001 | B7: APLICADA | C7: ILUSTRAÇÃO | D7: MIOLO | E7: 22 | F7: 1 | G7: 1 | I7: RESGATE | O7: Resgatar ilustração de bermuda. Vem do 1 NPC G23_MDN_LT página 14, g23_mdn_lt_1npc, código antigo i0210ec_1pmc_g19_mdn | W7: ec | X7: =IF(Tabela2[[#This Row],[SIGLA]]="","",VLOOKUP(Tabela2[[#This Row],[SIGLA]],créditos_base!B:C,2,0)) -> MÁRCIO GUERRA/ARQUIVO DA EDITORA | Z7: =Tabela2[[#This Row],[ILUSTRADOR CRIAÇÃO]] -> MÁRCIO GUERRA/ARQUIVO DA EDITORA | AD7: ="EF1 E001 HGC" -> EF1 E001 HGC
A8: i0108_1p011chg_g27_e001 | B8: APLICADA | C8: ILUSTRAÇÃO | D8: MIOLO | E8: 22 | F8: 1 | G8: 1 | I8: RESGATE | O8: Resgatar ilustração de tênis. Vem do 1 NPC G23_MDN_LT página 14, g23_mdn_lt_1npc, código antigo i0211ec_1pmc_g19_mdn | W8: ec | X8: =IF(Tabela2[[#This Row],[SIGLA]]="","",VLOOKUP(Tabela2[[#This Row],[SIGLA]],créditos_base!B:C,2,0)) -> MÁRCIO GUERRA/ARQUIVO DA EDITORA | Z8: =Tabela2[[#This Row],[ILUSTRADOR CRIAÇÃO]] -> MÁRCIO GUERRA/ARQUIVO DA EDITORA | AD8: ="EF1 E001 HGC" -> EF1 E001 HGC
A9: i0109_1p011chg_g27_e001 | B9: APLICADA | C9: ILUSTRAÇÃO | D9: MIOLO | E9: 22 | F9: 1 | G9: 1 | I9: RESGATE | O9: Resgatar ilustração de um menino de cueca. Vem do 1 NPC G23_MDN_LT página 14, g23_mdn_lt_1npc, código antigo i0212ec_1pmc_g19_mdn | W9: ec | X9: =IF(Tabela2[[#This Row],[SIGLA]]="","",VLOOKUP(Tabela2[[#This Row],[SIGLA]],créditos_base!B:C,2,0)) -> MÁRCIO GUERRA/ARQUIVO DA EDITORA | Z9: =Tabela2[[#This Row],[ILUSTRADOR CRIAÇÃO]] -> MÁRCIO GUERRA/ARQUIVO DA EDITORA | AD9: ="EF1 E001 HGC" -> EF1 E001 HGC
A10: i0111_1p011chg_g27_e001 | B10: APLICADA | C10: ILUSTRAÇÃO | D10: MIOLO | E10: 26 | F10: 1 | G10: 1 | I10: RESGATE | O10: Resgatar ilustração de menina com perspectiva de frente. Código antigo: i0203dd_1pmg_g19_mdn Vem do 1NPI_G23_MDN_LT P. 22 | W10: dd | X10: =IF(Tabela2[[#This Row],[SIGLA]]="","",VLOOKUP(Tabela2[[#This Row],[SIGLA]],créditos_base!B:C,2,0)) -> DANILO SANTOS/ARQUIVO DA EDITORA | Z10: =Tabela2[[#This Row],[ILUSTRADOR CRIAÇÃO]] -> DANILO SANTOS/ARQUIVO DA EDITORA | AD10: ="EF1 E001 HGC" -> EF1 E001 HGC
A11: i0112_1p011chg_g27_e001 | B11: APLICADA | C11: ILUSTRAÇÃO | D11: MIOLO | E11: 26 | F11: 1 | G11: 1 | I11: RESGATE | O11: Resgatar Ilustração de menina com perspectiva de costa. Código antigo: i0204dd_1pmg_g19_mdn. Vem do 1NPI_G23_MDN_LT P. 22 | W11: dd | X11: =IF(Tabela2[[#This Row],[SIGLA]]="","",VLOOKUP(Tabela2[[#This Row],[SIGLA]],créditos_base!B:C,2,0)) -> DANILO SANTOS/ARQUIVO DA EDITORA | Z11: =Tabela2[[#This Row],[ILUSTRADOR CRIAÇÃO]] -> DANILO SANTOS/ARQUIVO DA EDITORA | AD11: ="EF1 E001 HGC" -> EF1 E001 HGC
A12: i0113_1p011chg_g27_e001 | B12: APLICADA | C12: ILUSTRAÇÃO | D12: MIOLO | E12: 27 | F12: 1 | G12: 1 | I12: RESGATE | O12: Resgatar ilustração de menino com perspectiva de frente. Código antigo: i0205dd_1pmg_g19_mdn. Vem do 1NPI_G23_MDN_LT P. 23 | W12: dd | X12: =IF(Tabela2[[#This Row],[SIGLA]]="","",VLOOKUP(Tabela2[[#This Row],[SIGLA]],créditos_base!B:C,2,0)) -> DANILO SANTOS/ARQUIVO DA EDITORA | Z12: =Tabela2[[#This Row],[ILUSTRADOR CRIAÇÃO]] -> DANILO SANTOS/ARQUIVO DA EDITORA | AD12: ="EF1 E001 HGC" -> EF1 E001 HGC
A13: i0114_1p011chg_g27_e001 | B13: APLICADA | C13: ILUSTRAÇÃO | D13: MIOLO | E13: 27 | F13: 1 | G13: 1 | I13: RESGATE | O13: Resgatar ilustração de menino com perspectiva de costa. Código antigo: i0206dd_1pmg_g19_mdn. Vem do 1NPC G23 P. 23 | W13: dd | X13: =IF(Tabela2[[#This Row],[SIGLA]]="","",VLOOKUP(Tabela2[[#This Row],[SIGLA]],créditos_base!B:C,2,0)) -> DANILO SANTOS/ARQUIVO DA EDITORA | Z13: =Tabela2[[#This Row],[ILUSTRADOR CRIAÇÃO]] -> DANILO SANTOS/ARQUIVO DA EDITORA | AD13: ="EF1 E001 HGC" -> EF1 E001 HGC
A14: i0115_1p011chg_g27_e001 | B14: PRONTA | C14: ILUSTRAÇÃO | D14: MIOLO | E14: 28 | F14: 1 | G14: 1 | I14: AJUSTE | O14: Resgatar ilustração de mão esquerda. Código antigo: i0261co_1npg_g23_mdn_aj Veio do g23_mdn_lt_1npi_p25 | R14: 45891 | S14: 45895 | V14: 45895 | W14: co | X14: =IF(Tabela2[[#This Row],[SIGLA]]="","",VLOOKUP(Tabela2[[#This Row],[SIGLA]],créditos_base!B:C,2,0)) -> CAROLINE ROMÃO BEZERRA/ARQUIVO DA EDITORA | Y14: Rafaela Panissa | Z14: =Tabela2[[#This Row],[ILUSTRADOR CRIAÇÃO]] -> CAROLINE ROMÃO BEZERRA/ARQUIVO DA EDITORA | AA14: 13 | AB14: Resgate ajuste | AC14: FINALIZADO | AD14: ="EF1 E001 HGC" -> EF1 E001 HGC
A15: i0116_1p011chg_g27_e001 | B15: PRONTA | C15: ILUSTRAÇÃO | D15: MIOLO | E15: 28 | F15: 1 | G15: 1 | I15: AJUSTE | O15: Resgatar ilustração de mão direita i0264co_1npg_g23_mdn_aj Veio do g23_mdn_lt_1npi_p25 | R15: 45891 | S15: 45895 | V15: 45895 | W15: co | X15: =IF(Tabela2[[#This Row],[SIGLA]]="","",VLOOKUP(Tabela2[[#This Row],[SIGLA]],créditos_base!B:C,2,0)) -> CAROLINE ROMÃO BEZERRA/ARQUIVO DA EDITORA | Y15: Rafaela Panissa | Z15: =Tabela2[[#This Row],[ILUSTRADOR CRIAÇÃO]] -> CAROLINE ROMÃO BEZERRA/ARQUIVO DA EDITORA | AA15: 13 | AB15: Resgate ajuste | AC15: FINALIZADO | AD15: ="EF1 E001 HGC" -> EF1 E001 HGC
A16: i0117_1p011chg_g27_e001 | B16: PRONTA | C16: ILUSTRAÇÃO | D16: MIOLO | E16: 28 | F16: 1 | G16: 1 | I16: AJUSTE | O16: Resgatar ilustração de mão esquerda i0262co_1npg_g23_mdn_aj Veio do g23_mdn_lt_1npi_p25 | Q16: 30 | R16: 45891 | S16: 45895 | V16: 45895 | W16: co | X16: =IF(Tabela2[[#This Row],[SIGLA]]="","",VLOOKUP(Tabela2[[#This Row],[SIGLA]],créditos_base!B:C,2,0)) -> CAROLINE ROMÃO BEZERRA/ARQUIVO DA EDITORA | Y16: Rafaela Panissa | Z16: =Tabela2[[#This Row],[ILUSTRADOR CRIAÇÃO]] -> CAROLINE ROMÃO BEZERRA/ARQUIVO DA EDITORA | AA16: 13 | AB16: Resgate ajuste | AC16: FINALIZADO | AD16: ="EF1 E001 HGC" -> EF1 E001 HGC
A17: i0118_1p011chg_g27_e001 | B17: PRONTA | C17: ILUSTRAÇÃO | D17: MIOLO | E17: 28 | F17: 1 | G17: 1 | I17: AJUSTE | O17: Resgatar ilustração de mão esquerda. Código antigo: i0259co_1npg_g23_mdn_aj Veio do g23_mdn_lt_1npi_p25 | Q17: 30 | R17: 45891 | S17: 45895 | V17: 45895 | W17: co | X17: =IF(Tabela2[[#This Row],[SIGLA]]="","",VLOOKUP(Tabela2[[#This Row],[SIGLA]],créditos_base!B:C,2,0)) -> CAROLINE ROMÃO BEZERRA/ARQUIVO DA EDITORA | Y17: Rafaela Panissa | Z17: =Tabela2[[#This Row],[ILUSTRADOR CRIAÇÃO]] -> CAROLINE ROMÃO BEZERRA/ARQUIVO DA EDITORA | AA17: 13 | AB17: Resgate ajuste | AC17: FINALIZADO | AD17: ="EF1 E001 HGC" -> EF1 E001 HGC
A18: i0119_1p011chg_g27_e001 | B18: PRONTA | C18: ILUSTRAÇÃO | D18: MIOLO | E18: 28 | F18: 1 | G18: 1 | I18: AJUSTE | O18: Resgatar ilustração de mão direita. Código antigo: i0263co_1npg_g23_mdn_aj - Veio do g23_mdn_lt_1npi_p25 | R18: 45891 | S18: 45895 | V18: 45895 | W18: co | X18: =IF(Tabela2[[#This Row],[SIGLA]]="","",VLOOKUP(Tabela2[[#This Row],[SIGLA]],créditos_base!B:C,2,0)) -> CAROLINE ROMÃO BEZERRA/ARQUIVO DA EDITORA | Y18: Rafaela Panissa | Z18: =Tabela2[[#This Row],[ILUSTRADOR CRIAÇÃO]] -> CAROLINE ROMÃO BEZERRA/ARQUIVO DA EDITORA | AA18: 13 | AB18: Resgate ajuste | AC18: FINALIZADO | AD18: ="EF1 E001 HGC" -> EF1 E001 HGC
A19: i0120_1p011chg_g27_e001 | B19: PRONTA | C19: ILUSTRAÇÃO | D19: MIOLO | E19: 28 | F19: 1 | G19: 1 | I19: AJUSTE | O19: Resgatar ilustração de mão direita. Código antigo: i0260co_1npg_g23_mdn_aj - Veio do g23_mdn_lt_1npi_p25 | R19: 45891 | S19: 45895 | V19: 45895 | W19: co | X19: =IF(Tabela2[[#This Row],[SIGLA]]="","",VLOOKUP(Tabela2[[#This Row],[SIGLA]],créditos_base!B:C,2,0)) -> CAROLINE ROMÃO BEZERRA/ARQUIVO DA EDITORA | Y19: Rafaela Panissa | Z19: =Tabela2[[#This Row],[ILUSTRADOR CRIAÇÃO]] -> CAROLINE ROMÃO BEZERRA/ARQUIVO DA EDITORA | AA19: 13 | AB19: Resgate ajuste | AC19: FINALIZADO | AD19: ="EF1 E001 HGC" -> EF1 E001 HGC
A20: i0123_1p011chg_g27_e001 | B20: EXCLUIDA | C20: ILUSTRAÇÃO | D20: MIOLO | E20: 29 | F20: 1 | G20: 1 | I20: RESGATE | O20: Resgatar ilustração de uma menina de costas. Vem do 1NPC G23 _LT página 15, código antigo: i0213ly_1pmc_g19_mdn | W20: ly | X20: =IF(Tabela2[[#This Row],[SIGLA]]="","",VLOOKUP(Tabela2[[#This Row],[SIGLA]],créditos_base!B:C,2,0)) -> LISLLEY GOMES FEIGE/ARQUIVO DA EDITORA | Z20: =Tabela2[[#This Row],[ILUSTRADOR CRIAÇÃO]] -> LISLLEY GOMES FEIGE/ARQUIVO DA EDITORA | AD20: ="EF1 E001 HGC" -> EF1 E001 HGC
A21: i0124_1p011chg_g27_e001 | B21: APLICADA | C21: ILUSTRAÇÃO | D21: MIOLO | E21: 30 | F21: 1 | G21: 1 | I21: RESGATE | O21: Resgatar ilustração de crianças uma deitada em cima de um papel e a outra fazendo um mapa do corpo. Código antigo: i0286dd_1pmg_g19_mdn. Vem do 1NPI G23 LT P. 26 | W21: dd | X21: =IF(Tabela2[[#This Row],[SIGLA]]="","",VLOOKUP(Tabela2[[#This Row],[SIGLA]],créditos_base!B:C,2,0)) -> DANILO SANTOS/ARQUIVO DA EDITORA | Z21: =Tabela2[[#This Row],[ILUSTRADOR CRIAÇÃO]] -> DANILO SANTOS/ARQUIVO DA EDITORA | AD21: ="EF1 E001 HGC" -> EF1 E001 HGC
A22: i0125_1p011chg_g27_e001 | B22: APLICADA | C22: ILUSTRAÇÃO | D22: MIOLO | E22: 31 | F22: 1 | G22: 1 | I22: RESGATE | O22: Resgatar ilustração de professora segurando o papel que as crianças da ilustração anterior desenharam, código antigo: i0287dd_1pmg_g19_mdn. Vem do 1NPC_LT_G23_MDN_P.27 | W22: dd | X22: =IF(Tabela2[[#This Row],[SIGLA]]="","",VLOOKUP(Tabela2[[#This Row],[SIGLA]],créditos_base!B:C,2,0)) -> DANILO SANTOS/ARQUIVO DA EDITORA | Z22: =Tabela2[[#This Row],[ILUSTRADOR CRIAÇÃO]] -> DANILO SANTOS/ARQUIVO DA EDITORA | AD22: ="EF1 E001 HGC" -> EF1 E001 HGC
A23: i0126_1p011chg_g27_e001 | B23: APLICADA | C23: ILUSTRAÇÃO | D23: MIOLO | E23: 31 | F23: 1 | G23: 1 | I23: RESGATE | O23: Resgatar ilustração de professora com crianças colorindo o desenho que fizeram, código antigo: i0288dd_1pmg_g19_mdn Vem do 1NPC_LT_G23_MDN_P.27 | W23: dd | X23: =IF(Tabela2[[#This Row],[SIGLA]]="","",VLOOKUP(Tabela2[[#This Row],[SIGLA]],créditos_base!B:C,2,0)) -> DANILO SANTOS/ARQUIVO DA EDITORA | Z23: =Tabela2[[#This Row],[ILUSTRADOR CRIAÇÃO]] -> DANILO SANTOS/ARQUIVO DA EDITORA | AD23: ="EF1 E001 HGC" -> EF1 E001 HGC
A24: i0127_1p011chg_g27_e001 | B24: APLICADA | C24: ILUSTRAÇÃO | D24: MIOLO | E24: 32 | F24: 1 | G24: 1 | I24: AJUSTE | O24: Resgatar ilustração de menino de frente e costas com uma linha no meio separando os lados, código antigo: i0320dd_1pmg_g19_mdn. Vem do 1NPC_LT_G23_MDN_P.28 Ajuste: ajustar a cor do boneco para deixar na mesma tonalidade da pele do boneco da ilustração anterior: i0126_1p011chg_g27_e001. | Q24: 1 | R24: 45740 | S24: 45740 | V24: 45740 | W24: dd | X24: =IF(Tabela2[[#This Row],[SIGLA]]="","",VLOOKUP(Tabela2[[#This Row],[SIGLA]],créditos_base!B:C,2,0)) -> DANILO SANTOS/ARQUIVO DA EDITORA | Y24: Felipe Grigoli | Z24: =Tabela2[[#This Row],[ILUSTRADOR CRIAÇÃO]] -> DANILO SANTOS/ARQUIVO DA EDITORA | AA24: 8 | AB24: Ajuste Simples | AC24: FINALIZADO | AD24: ="EF1 E001 HGC" -> EF1 E001 HGC
A25: i0128_1p011chg_g27_e001 | B25: PRONTA | C25: ILUSTRAÇÃO | D25: MIOLO | E25: 34 | F25: 1 | G25: 1 | I25: AJUSTE | O25: Resgatar ilustração de menina tomando café da manhã veio do g23_mdn_lt_1npc_p038, código antigo i0453aec_1pmc_g19_mdn. Vem do 1NPC_G23_LT_MDN_P38 | Q25: 30 | R25: 45891 | S25: 45895 | V25: 45895 | W25: ec | X25: =IF(Tabela2[[#This Row],[SIGLA]]="","",VLOOKUP(Tabela2[[#This Row],[SIGLA]],créditos_base!B:C,2,0)) -> MÁRCIO GUERRA/ARQUIVO DA EDITORA | Y25: Rafaela Panissa | Z25: =Tabela2[[#This Row],[ILUSTRADOR CRIAÇÃO]] -> MÁRCIO GUERRA/ARQUIVO DA EDITORA | AA25: 13 | AB25: Resgate ajuste | AC25: FINALIZADO | AD25: ="EF1 E001 HGC" -> EF1 E001 HGC
A26: i0129_1p011chg_g27_e001 | B26: PRONTA | C26: ILUSTRAÇÃO | D26: MIOLO | E26: 34 | F26: 1 | G26: 1 | I26: AJUSTE | O26: Resgatar ilustração de crianças brincando veio do g23_mdn_lt_1npc_p038 código antigo i0453bec_1pmc_g19_mdn. Vem do 1NPC_G23_LT_MDN_P38 | Q26: 30 | R26: 45891 | S26: 45895 | V26: 45895 | W26: ec | X26: =IF(Tabela2[[#This Row],[SIGLA]]="","",VLOOKUP(Tabela2[[#This Row],[SIGLA]],créditos_base!B:C,2,0)) -> MÁRCIO GUERRA/ARQUIVO DA EDITORA | Y26: Rafaela Panissa | Z26: =Tabela2[[#This Row],[ILUSTRADOR CRIAÇÃO]] -> MÁRCIO GUERRA/ARQUIVO DA EDITORA | AA26: 13 | AB26: Resgate ajuste | AC26: FINALIZADO | AD26: ="EF1 E001 HGC" -> EF1 E001 HGC
A27: i0130_1p011chg_g27_e001 | B27: PRONTA | C27: ILUSTRAÇÃO | D27: MIOLO | E27: 34 | F27: 1 | G27: 1 | I27: AJUSTE | O27: Resgatar ilustração de menina brincando com cachorro veio do g23_mdn_lt_1npc_p038, código antigo i0453cec_1pmc_g19_mdn. Vem do 1NPC_G23_LT_MDN_P38 | Q27: 30 | R27: 45891 | S27: 45895 | V27: 45895 | W27: ec | X27: =IF(Tabela2[[#This Row],[SIGLA]]="","",VLOOKUP(Tabela2[[#This Row],[SIGLA]],créditos_base!B:C,2,0)) -> MÁRCIO GUERRA/ARQUIVO DA EDITORA | Y27: Rafaela Panissa | Z27: =Tabela2[[#This Row],[ILUSTRADOR CRIAÇÃO]] -> MÁRCIO GUERRA/ARQUIVO DA EDITORA | AA27: 13 | AB27: Resgate ajuste | AC27: FINALIZADO | AD27: ="EF1 E001 HGC" -> EF1 E001 HGC
A28: i0131_1p011chg_g27_e00 | B28: PRONTA | C28: ILUSTRAÇÃO | D28: MIOLO | E28: 34 | F28: 1 | G28: 1 | I28: AJUSTE | O28: Resgatar ilustração de menina dando descarga veio do g23_mdn_lt_1npc_p038, código antigo i0453dec_1pmc_g19_mdn. Vem do 1NPC_G23_LT_MDN_P38 | Q28: 30 | R28: 45891 | S28: 45895 | V28: 45895 | W28: ec | X28: =IF(Tabela2[[#This Row],[SIGLA]]="","",VLOOKUP(Tabela2[[#This Row],[SIGLA]],créditos_base!B:C,2,0)) -> MÁRCIO GUERRA/ARQUIVO DA EDITORA | Y28: Rafaela Panissa | Z28: =Tabela2[[#This Row],[ILUSTRADOR CRIAÇÃO]] -> MÁRCIO GUERRA/ARQUIVO DA EDITORA | AA28: 13 | AB28: Resgate ajuste | AC28: FINALIZADO | AD28: ="EF1 E001 HGC" -> EF1 E001 HGC
A29: i0132_1p011chg_g27_e001 | B29: APLICADA | C29: ILUSTRAÇÃO | D29: MIOLO | E29: 35 | F29: 1 | G29: 1 | I29: RESGATE | O29: Resgatar ilustração de menina escovando os dentes veio do g23_mdn_lt_1npc_p039, código antigo i0454bec_1pmc_g19_mdn. Vem do 1NPC_G23_LT_MDN_P39 | W29: ec | X29: =IF(Tabela2[[#This Row],[SIGLA]]="","",VLOOKUP(Tabela2[[#This Row],[SIGLA]],créditos_base!B:C,2,0)) -> MÁRCIO GUERRA/ARQUIVO DA EDITORA | Z29: =Tabela2[[#This Row],[ILUSTRADOR CRIAÇÃO]] -> MÁRCIO GUERRA/ARQUIVO DA EDITORA | AD29: ="EF1 E001 HGC" -> EF1 E001 HGC
A30: i0133_1p011chg_g27_e001 | B30: APLICADA | C30: ILUSTRAÇÃO | D30: MIOLO | E30: 35 | F30: 1 | G30: 1 | I30: AJUSTE | O30: Resgatar ilustração de menina tomando banho veio do g23_mdn_lt_1npc_p039 código antigo - i0454aec_1pmc_g19_mdn. Vem do 1NPC_G23_LT_MDN_P39. Ajuste: retirar a água que está saindo do chuveiro e as gotinhas de água ao redor da cabeça da personagem. | Q30: 1 | R30: 45740 | S30: 45740 | V30: 45772 | W30: ec | X30: =IF(Tabela2[[#This Row],[SIGLA]]="","",VLOOKUP(Tabela2[[#This Row],[SIGLA]],créditos_base!B:C,2,0)) -> MÁRCIO GUERRA/ARQUIVO DA EDITORA | Y30: Felipe Grigoli | Z30: =Tabela2[[#This Row],[ILUSTRADOR CRIAÇÃO]] -> MÁRCIO GUERRA/ARQUIVO DA EDITORA | AA30: 13 | AB30: Ajuste Simples | AC30: FINALIZADO | AD30: ="EF1 E001 HGC" -> EF1 E001 HGC
A31: i0134_1p011chg_g27_e001 | B31: APLICADA | C31: ILUSTRAÇÃO | D31: MIOLO | E31: 35 | F31: 1 | G31: 1 | I31: RESGATE | O31: Resgatar Ilustração de mãe de menina cortando as unhas da sua filha veio do g23_mdn_lt_1npc_p039, código antigo i0454cec_1pmc_g19_mdn. Vem do 1NPC_G23_LT_MDN_P39 | W31: ec | X31: =IF(Tabela2[[#This Row],[SIGLA]]="","",VLOOKUP(Tabela2[[#This Row],[SIGLA]],créditos_base!B:C,2,0)) -> MÁRCIO GUERRA/ARQUIVO DA EDITORA | Z31: =Tabela2[[#This Row],[ILUSTRADOR CRIAÇÃO]] -> MÁRCIO GUERRA/ARQUIVO DA EDITORA | AD31: ="EF1 E001 HGC" -> EF1 E001 HGC
A32: i0139_1p011chg_g27_e001 | B32: APLICADA | C32: ILUSTRAÇÃO | D32: MIOLO | E32: 38 | F32: 1 | G32: 1 | I32: RESGATE | O32: Resgatar ilustração de menino indo escovar os dentes veio do g23_mdn_lt_1npc_p042, código antigo: i0631ly_1npc_g23_mdn_aj | W32: ly | X32: =IF(Tabela2[[#This Row],[SIGLA]]="","",VLOOKUP(Tabela2[[#This Row],[SIGLA]],créditos_base!B:C,2,0)) -> LISLLEY GOMES FEIGE/ARQUIVO DA EDITORA | Z32: =Tabela2[[#This Row],[ILUSTRADOR CRIAÇÃO]] -> LISLLEY GOMES FEIGE/ARQUIVO DA EDITORA | AD32: ="EF1 E001 HGC" -> EF1 E001 HGC
A33: i0140_1p011chg_g27_e001 | B33: APLICADA | C33: ILUSTRAÇÃO | D33: MIOLO | E33: 39 | F33: 1 | G33: 1 | I33: RESGATE | O33: Resgatar ilustração de pessoa escovando os dentes de cima para baixo, veio do g23_mdn_lt_1npc_p043, código antigo: i0456alu_1pmc_g19_mdn | W33: lu | X33: =IF(Tabela2[[#This Row],[SIGLA]]="","",VLOOKUP(Tabela2[[#This Row],[SIGLA]],créditos_base!B:C,2,0)) -> LUCIANE MORI/ARQUIVO DA EDITORA | Z33: =Tabela2[[#This Row],[ILUSTRADOR CRIAÇÃO]] -> LUCIANE MORI/ARQUIVO DA EDITORA | AD33: ="EF1 E001 HGC" -> EF1 E001 HGC
A34: i0141_1p011chg_g27_e001 | B34: APLICADA | C34: ILUSTRAÇÃO | D34: MIOLO | E34: 39 | F34: 1 | G34: 1 | I34: RESGATE | O34: Resgatar ilustração de pessoa escovando os dentes de baixo para cima, veio do g23_mdn_lt_1npc_p043, código antigo: i0456blu_1pmc_g19_mdn | W34: lu | X34: =IF(Tabela2[[#This Row],[SIGLA]]="","",VLOOKUP(Tabela2[[#This Row],[SIGLA]],créditos_base!B:C,2,0)) -> LUCIANE MORI/ARQUIVO DA EDITORA | Z34: =Tabela2[[#This Row],[ILUSTRADOR CRIAÇÃO]] -> LUCIANE MORI/ARQUIVO DA EDITORA | AD34: ="EF1 E001 HGC" -> EF1 E001 HGC
A35: i0142_1p011chg_g27_e001 | B35: APLICADA | C35: ILUSTRAÇÃO | D35: MIOLO | E35: 39 | F35: 1 | G35: 1 | I35: RESGATE | O35: Resgatar ilustração de pessoa escovando os dentes com movimento vai e Vem veio do g23_mdn_lt_1npc_p043, código antigo: i0456clu_1pmc_g19_mdn | W35: lu | X35: =IF(Tabela2[[#This Row],[SIGLA]]="","",VLOOKUP(Tabela2[[#This Row],[SIGLA]],créditos_base!B:C,2,0)) -> LUCIANE MORI/ARQUIVO DA EDITORA | Z35: =Tabela2[[#This Row],[ILUSTRADOR CRIAÇÃO]] -> LUCIANE MORI/ARQUIVO DA EDITORA | AD35: ="EF1 E001 HGC" -> EF1 E001 HGC
A36: i0143_1p011chg_g27_e001 | B36: APLICADA | C36: ILUSTRAÇÃO | D36: MIOLO | E36: 39 | F36: 1 | G36: 1 | I36: RESGATE | O36: Resgatar ilustração de pessoa escovando os dentes de com o movimento sobe e desce, veio do g23_mdn_lt_1npc_p043, código antigo: i0456dlu_1pmc_g19_mdn | W36: lu | X36: =IF(Tabela2[[#This Row],[SIGLA]]="","",VLOOKUP(Tabela2[[#This Row],[SIGLA]],créditos_base!B:C,2,0)) -> LUCIANE MORI/ARQUIVO DA EDITORA | Z36: =Tabela2[[#This Row],[ILUSTRADOR CRIAÇÃO]] -> LUCIANE MORI/ARQUIVO DA EDITORA | AD36: ="EF1 E001 HGC" -> EF1 E001 HGC
A37: i0144_1p011chg_g27_e001 | B37: APLICADA | C37: ILUSTRAÇÃO | D37: MIOLO | E37: 39 | F37: 1 | G37: 1 | I37: RESGATE | O37: Resgatar ilustração de pessoa segurando o fio dental veio do g23_mdn_lt_1npc_p043, código antigo: i0457alu_1pmc_g19_mdn | W37: lu | X37: =IF(Tabela2[[#This Row],[SIGLA]]="","",VLOOKUP(Tabela2[[#This Row],[SIGLA]],créditos_base!B:C,2,0)) -> LUCIANE MORI/ARQUIVO DA EDITORA | Z37: =Tabela2[[#This Row],[ILUSTRADOR CRIAÇÃO]] -> LUCIANE MORI/ARQUIVO DA EDITORA | AD37: ="EF1 E001 HGC" -> EF1 E001 HGC
A38: i0145_1p011chg_g27_e001 | B38: APLICADA | C38: ILUSTRAÇÃO | D38: MIOLO | E38: 39 | F38: 1 | G38: 1 | I38: RESGATE | O38: Resgatar ilustração de pessoa passando o fio dental veio do g23_mdn_lt_1npc_p043, código antigo: i0457blu_1pmc_g19_mdn | W38: lu | X38: =IF(Tabela2[[#This Row],[SIGLA]]="","",VLOOKUP(Tabela2[[#This Row],[SIGLA]],créditos_base!B:C,2,0)) -> LUCIANE MORI/ARQUIVO DA EDITORA | Z38: =Tabela2[[#This Row],[ILUSTRADOR CRIAÇÃO]] -> LUCIANE MORI/ARQUIVO DA EDITORA | AD38: ="EF1 E001 HGC" -> EF1 E001 HGC
A39: i0146_1p011chg_g27_e001 | B39: EXCLUIDA | C39: ILUSTRAÇÃO | D39: MIOLO | E39: 40 | F39: 1 | G39: 1 | I39: RESGATE | O39: Resgatar ilustração de menino tomando banho veio do g23_mdn_lt_1npc_p044, código antigo: i0409ly_1pmc_g19_mdn | W39: ly | X39: =IF(Tabela2[[#This Row],[SIGLA]]="","",VLOOKUP(Tabela2[[#This Row],[SIGLA]],créditos_base!B:C,2,0)) -> LISLLEY GOMES FEIGE/ARQUIVO DA EDITORA | Z39: =Tabela2[[#This Row],[ILUSTRADOR CRIAÇÃO]] -> LISLLEY GOMES FEIGE/ARQUIVO DA EDITORA | AD39: ="EF1 E001 HGC" -> EF1 E001 HGC
A40: i0147_1p011chg_g27_e001 | B40: APLICADA | C40: ILUSTRAÇÃO | D40: MIOLO | E40: 40 | F40: 1 | G40: 1 | I40: RESGATE | O40: Resgatar ilustração de traço de uma toalha veio do g23_mdn_lt_1npc_p044, código antigo: i0410bly_1pmc_g19_mdn | W40: ly | X40: =IF(Tabela2[[#This Row],[SIGLA]]="","",VLOOKUP(Tabela2[[#This Row],[SIGLA]],créditos_base!B:C,2,0)) -> LISLLEY GOMES FEIGE/ARQUIVO DA EDITORA | Z40: =Tabela2[[#This Row],[ILUSTRADOR CRIAÇÃO]] -> LISLLEY GOMES FEIGE/ARQUIVO DA EDITORA | AD40: ="EF1 E001 HGC" -> EF1 E001 HGC
...

Sheet créditos_base
A1: CRÉDITOS GERAIS DA MODERNA PARA REFERÊNCIA - EF1
A2: Nome do ilustrador | B2: Sigla Arte | C2: Crédito
A3: Nome do ilustrador | B3: Sigla Arte | C3: Crédito
A4: Acervo da editora | B4: xx | C4: ARQUIVO DA EDITORA
A5: Sigla ZZ (ver documento de ils. técnicas) | B5: zz | C5: VER DOCUMENTO DE ILS. TÉCNICAS
A6: ILUSTRAÇOES DE PROVAS OFICIAIS (somente se não houver crédito) | B6: yv | C6: NOME DA UNIVERSIDADE/ANO - UNICAMP 2024 NOME DO ILUSTRADOR (AJUSTE)/ARQUIVO DA EDITORA/UNIVERSIDADE ANO
A7: ILUSTRAÇÕES DE PLACAS DE TRÂNSITO | B7: yy | C7: NOME DO ILUSTRADOR/ARQUIVO DA EDITORA
A8: ILUSTRAÇÕES DE BANDEIRAS DE PAÍS | B8: yp | C8: NOME DO ILUSTRADOR/ARQUIVO DA EDITORA
A9: ILUSTRAÇÕES DE BANDEIRAS DE ESTADO | B9: ye | C9: NOME DO ILUSTRADOR/ARQUIVO DA EDITORA
A10: ILUSTRAÇÕES GERADAS POR PROGRAMAS C/ IA | B10: ia | C10: ARQUIVO DA EDITORA
A11: Arte | B11: a | C11: ARTE
A12: 3 Pixel Studio | B12: px | C12: ROBSON OLIVIERIA/ARQUIVO DA EDITORA
A13: A7 Estudio | B13: ao | C13: JORGE RIBEIRO/ARQUIVO DA EDITORA
... A41: Beatriz Mayumi | B41: bm | C41: BEATRIZ MAYUMI/ARQUIVO DA EDITORA
A42: Belli Studio Design | B42: bl
A43: Bernardo França | B43: be | C43: BERNARDO FRANÇA/ARQUIVO DA EDITORA
A44: Bianca Nazari | B44: bi | C44: BIANCA NAZARI/ARQUIVO DA EDITORA
A45: Brenda Bossato | B45: bd | C45: BRENDA BOSSATO/ARQUIVO DA EDITORA
A46: Brenda Goes | B46: bg | C46: BRENDA GOES/ARQUIVO DA EDITORA
A47: Bruna Campos | B47: bp | C47: BRUNA CAMPOS/ARQUIVO DA EDITORA
A48: Brunna Mancuso | B48: bs | C48: BRUNNA MANCUSO/ARQUIVO DA EDITORA
A49: Bruna Menezes | B49: bz | C49: BRUNA MENEZES/ARQUIVO DA EDITORA
A50: Bruno Badain | B50: bb | C50: BRUNO BADAIN/ARQUIVO DA EDITORA
A51: Bruno H. S. Cerkuenik | B51: bc | C51: BRUNO CERKUENIK/ARQUIVO DA EDITORA
A52: Bruno Nunes Coelho | B52: bn | C52: BRUNO NUNES/ARQUIVO DA EDITORA
A53: Bruno Oliveira Sampaio | B53: br | C53: BRUNO SAMPAIO/ARQUIVO DA EDITORA
A54: Bruno Rosal de Vasconcelos | B54: bu
A55: Caio Hideki Takaso Tanaka | B55: ct | C55: CAIO TANAKA/ARQUIVO DA EDITORA
A56: Camila Cristiane Pereira dos Santos | B56: cd
A57: Camila Ferreira Carmona | B57: ca | C57: CAMILA CARMONA/ARQUIVO DA EDITORA
A58: Carlitos Pinheiro | B58: cq | C58: CARLITOS PINHEIRO/ARQUIVO DA EDITORA
A59: Carlos Alberto Borin Junior | B59: cj | C59: CARLOS BORIN/ARQUIVO DA EDITORA
A60: Carlos Eduardo Nascimento | B60: cn | C60: CARLOS EDUARDO NASCIMENTO/ARQUIVO DA EDITORA
A61: Carmen Ferreira Martinez | B61: cc | C61: CARMEN MARTINEZ/ARQUIVO DA EDITORA
A62: Carol Rempto | B62: cw | C62: CAROL REMPTO/ARQUIVO DA EDITORA
A63: Carol Sartori | B63: cx | C63: CAROL SARTORI/ARQUIVO DA EDITORA
A64: Carolina Coroa | B64: kk | C64: CAROLINA COROA/ARQUIVO DA EDITORA
A65: Caroline Romão Bezerra | B65: co | C65: CAROLINE ROMÃO BEZERRA/ARQUIVO DA EDITORA
A66: Cartoon Pro | B66: cp
A67: Cássio Bittencourt | B67: cs | C67: CÁSSIO BITTENCOURT/ARQUIVO DA EDITORA
...

Sheet metadados
A1: PRÉ-EDIÇÃO | B1: ILUSTRAÇÃO | C1: CAPA | D1: 1 | E1: AJUSTE | F1: SCRIBA | G1: 1 | H1: PREVISAO
A2: EDICAO_EQUIPE | B2: IL TEC ARTE | C2: APRESENT. | D2: 2 | E2: NOVA | F2: FTD | G2: 2 | H2: FINALIZADO
A3: EDICAO_ARTE | B3: IL + FOTO | C3: SUMÁRIO | D3: 3 | E3: RESGATE | F3: MDN | G3: 3 | H3: FINALIZADO RAFE
A4: ILUSTRANDO | B4: MAPA | C4: ABERTURA | D4: 4 | F4: SABER | G4: 4 | H4: PAGO
A5: AVALIANDO | B5: GRÁFICO | C5: MIOLO | D5: 5 | F5: SM | G5: 5 | H5: PAGO RAFE
A6: AJUSTANDO | B6: LINHA TEMPO | C6: PAG.ESPECIAL | D6: 6 | F6: SCP | G6: 6
A7: FINALIZANDO | B7: INFOGRÁFICO | C7: MP-G | D7: ÚNICO | F7: ABR | G7: 7
A8: PRONTA | C8: MP-E | F8: BASE | G8: 8
A9: APLICADA | F9: IBEP | G9: 9
A10: EXCLUIDA | F10: LEYA | G10: 10
F11: SARAIVA | G11: 11
F12: SANTILLANA | G12: 12
F13: QUINTETO | G13: 13
G14: 14
