Workbook

Sheet ilustração
A1: retranca | B1: status | C1: categoria | D1: localizacao | E1: pagina | F1: volume | G1: unidade | H1: capitulo_secao | I1: tipo | J1: NOME DA OBRA PARA RESGATE | K1: PÁGINA PARA RESGATE | L1: VOLUME PARA RESGATE | M1: VERSÃO PARA RESGATE | N1: PROPRIEDADE | O1: descricao | P1: observacao_edit_nuc | Q1: lote | R1: data_liberacao_para_arte | S1: data_envio_pedido | T1: data_recebimento_rafe | U1: data_retorno_rafe | V1: data_recebimento_finalizada | W1: sigla | X1: ilustrador | Y1: ilustrador_ajuste | Z1: credito | AA1: classificacao | AB1: observacao_arte | AC1: pagamento | AD1: projeto | AE1: componente | AF1: ilustrador_resgate
A2: i0102_3p012ef_g27_e002 | B2: APLICADA | C2: ILUSTRAÇÃO | D2: MP-E | F2: 3 | G2: 1 | I2: NOVA | O2: Ilustrar uma quadra escolar com uma espiral grande desenhada no chão e uma menina de cabelo preto preso e pela morena, passando giz de outra cor por cima. Tem que parecer que a espiral foi desenhada com giz escolar. No vídeo a seguir da para ter uma noção melhor. https://www.youtube.com/watch?app=desktop&v=-5GK_OWGQPI | Q2: 5 | R2: 45849 | S2: 45855 | T2: 45856 | U2: 45859 | V2: 45860 | W2: jx | X2: =IF(Tabela2[[#This Row],[sigla]]="","",VLOOKUP(Tabela2[[#This Row],[sigla]],créditos_base!B:C,2,0)) -> JULIANA DACOSTA/ARQUIVO DA EDITORA | Z2: =Tabela2[[#This Row],[ilustrador]] -> JULIANA DACOSTA/ARQUIVO DA EDITORA | AA2: 5 | AB2: R: 18/07 ; F: 22/07 | AC2: PAGO | AD2: ="Plantar" -> Plantar | AE2: ="Educação Física" -> Educação Física
A3: i0103_3p012ef_g27_e002 | B3: PRONTA | C3: ILUSTRAÇÃO | D3: MP-E | F3: 3 | G3: 1 | I3: NOVA | O3: Ilustrar um estudante em pé, em uma quadra escolar, com um dos joelhos flexionados, conforme referência, apontando com o dedo para a perna de uma criança e Ilustrar estudantes sentados em linha, sendo alguns com uma das pernas flexionadas e outros com as duas esticadas, conforme exemplo abaixo. Biotipos das crianças do chão: Ilustrar 4 crianças: - uma menina branca do cabelo castanho e encaracolado com óculos de grau bem forte; - Um menino negro mais gordinho; - Uma menina negra com cabelo preso; Um menino pardo com cabelo mais comprido; Criança em pé: - Menino negro, como na referência | Q3: 5 | R3: 45849 | S3: 45854 | T3: 45861 | U3: 45863 | V3: 45867 | W3: la | X3: =IF(Tabela2[[#This Row],[sigla]]="","",VLOOKUP(Tabela2[[#This Row],[sigla]],créditos_base!B:C,2,0)) -> LEONARDO DE MOURA AMARAL/ARQUIVO DA EDITORA | Z3: =Tabela2[[#This Row],[ilustrador]] -> LEONARDO DE MOURA AMARAL/ARQUIVO DA EDITORA | AA3: 4 | AB3: R: 21/07 ; F: 29/07 | AC3: PAGO | AD3: ="Plantar" -> Plantar | AE3: ="Educação Física" -> Educação Física
A4: i0104_1p012ef_g27_e002 | B4: AVALIANDO | C4: ILUSTRAÇÃO | D4: MP-E | E4: 23 | F4: 1 | G4: 1 | I4: NOVA | O4: ilustração de uma quadra escolar com dois círculos no chão desenhados com giz, em cada círculo deve ter quatro crianças ajoelhadas ou agachadas com biotipos diferentes (um menino loiro/branco mais gordinho com braço mecânico (ele deve estar segurando a bolinha na outra mão), um menino e uma menina negros e uma menina com traços étnicos indígenas. No outro círculo, um menino loiro/branco usando aparelho auditivo, uma menina negra de óculos, um menino indígena e uma menina oriental mais gordinha. Todos, de ambas as rodas, devem estar segurando uma bolinha de gude colorida na mão. Algumas crianças podem estar com a posição de dedilhar a bolinha apontando para o centro do círculo. A ilustração deve representar um clima descontraído Sugestão de ilustração como referência: https://pt.vecteezy.com/arte-vetorial/6981173-ao-ar-livre-parque-com-criancas-jogando-bola-de-gude | Q4: 1 | R4: 45807 | S4: 45813 | T4: 45819 | U4: 45821 | V4: 45826 | W4: dn | X4: =IF(Tabela2[[#This Row],[sigla]]="","",VLOOKUP(Tabela2[[#This Row],[sigla]],créditos_base!B:C,2,0)) -> GUILHERME RODRIGUES/ARQUIVO DA EDITORA | Z4: =Tabela2[[#This Row],[ilustrador]] -> GUILHERME RODRIGUES/ARQUIVO DA EDITORA | AA4: 4 | AB4: R: 10/06 ; R2: 16/06 ; F: 18/06 | AC4: PAGO | AD4: ="Plantar" -> Plantar | AE4: ="Educação Física" -> Educação Física
A5: i0301_3p012ef_g27_e002 | B5: APLICADA | C5: ILUSTRAÇÃO | D5: MP-E | F5: 3 | G5: 2 | I5: NOVA | O5: Ilustrar o jogo de bets, com quartetos posicionados na quadra, como na primeira imagem. A linguagem da ilustração, porém, pode ser técnica, como na segunda imagem. Posicionar os quartetos como na segunda imagem e indicar as flechas com as cotas. OBS: No lugar de escrever ‘dupla de lançadores’ escrever “Dupla de defensores” Não precisa escrever “Casinha dentro da base” No lugar da garrafa pet, ilustrar um cone. | Q5: 6 | R5: 45852 | S5: 45853 | V5: 45859 | W5: rm | X5: =IF(Tabela2[[#This Row],[sigla]]="","",VLOOKUP(Tabela2[[#This Row],[sigla]],créditos_base!B:C,2,0)) -> HELOÍSA PINTARELLI/ARQUIVO DA EDITORA | Z5: =Tabela2[[#This Row],[ilustrador]] -> HELOÍSA PINTARELLI/ARQUIVO DA EDITORA | AA5: 5 | AB5: F: 21/07 | AC5: PAGO | AD5: ="Plantar" -> Plantar | AE5: ="Educação Física" -> Educação Física
A6: i0302_3p012ef_g27_e002 | B6: APLICADA | C6: ILUSTRAÇÃO | D6: MP-E | F6: 3 | G6: 2 | I6: NOVA | O6: Ilustrar o jogo de baseball adaptado ao contexto escolar conforme modelo abaixo utilizando uma linguagem tecnica, utilizando símbolos para as crianças vestindo coletes de cores diferentes para diferenciar o ataque e defesa, nao utilizar os mesmos símbolos da referência para não ser plagio A referência visual da imagem abaixo está no link: https://www.institutoclaro.org.br/educacao/para-ensinar/planos-de-aula/esportes-de-campo-e-taco-do-beisebol-ao-criquete/ https://www.efdeportes.com/efd119/beisebol-nas-aulas-educacao-fisica-escolar.htm | Q6: 6 | R6: 45852 | S6: 45853 | V6: 45859 | W6: rm | X6: =IF(Tabela2[[#This Row],[sigla]]="","",VLOOKUP(Tabela2[[#This Row],[sigla]],créditos_base!B:C,2,0)) -> HELOÍSA PINTARELLI/ARQUIVO DA EDITORA | Z6: =Tabela2[[#This Row],[ilustrador]] -> HELOÍSA PINTARELLI/ARQUIVO DA EDITORA | AA6: 6 | AB6: F: 21/07 | AC6: PAGO | AD6: ="Plantar" -> Plantar | AE6: ="Educação Física" -> Educação Física
A7: i0305_1p012ef_g27_e002 | B7: APLICADA | C7: ILUSTRAÇÃO | D7: MP-E | E7: 48 | F7: 1 | G7: 2 | I7: NOVA | O7: Arte, por favor ilustrar crianças de frente para um alvo desenhado no chão, com uma bola parecida com bola de tênis em um dos círculos. Variar etnias e biotipos: um menino com vitiligo, uma menina loira mais gordinha, um menino e uma menina negros, e um menino ruivo em cadeira de rodas. O professor deve estar próximo deles. Ver referência em: https://www.facebook.com/photo.php?fbid=1187259244647375&id=1157434354296531&set=a.1157474514292515 (obs: não precisa ter os cones) | Q7: 2 | R7: 45813 | S7: 45817 | T7: 45819 | U7: 45821 | V7: 45824 | W7: ig | X7: =IF(Tabela2[[#This Row],[sigla]]="","",VLOOKUP(Tabela2[[#This Row],[sigla]],créditos_base!B:C,2,0)) -> FABIO EIJI SIRASUMA/ARQUIVO DA EDITORA | Z7: =Tabela2[[#This Row],[ilustrador]] -> FABIO EIJI SIRASUMA/ARQUIVO DA EDITORA | AA7: 4 | AB7: R: 11/06 ; F: 16/06 | AC7: PAGO | AD7: ="Plantar" -> Plantar | AE7: ="Educação Física" -> Educação Física
A8: i0506_1p012ef_g27_e002 | B8: APLICADA | C8: ILUSTRAÇÃO | D8: MP-E | E8: 63 | F8: 1 | G8: 3 | I8: NOVA | O8: Ilustrar crianças brincando da brincadeira Saltando o feijão, com base na referência a seguir, retirada do Instragram https://www.instagram.com/p/DC7PQYWREVc/ Uma criança deve estar no centro, em um lugar aparentando um pátio de escola, segurando uma corda e girando em movimentos circulares, assim como na imagem, para que as crianças pulem-na. Ilustrar 4 crianças brincando, um menino e uma menina negros, um menino com traços étnicos indígenas, e uma menina ruiva com aparelho dentário ou auditivo. Ilustrar a imagem do professor, pode ser em sombra, ao lado das crianças. | Q8: 3 | R8: 45821 | S8: 45824 | T8: 45826 | U8: 45826 | V8: 45832 | W8: jl | X8: =IF(Tabela2[[#This Row],[sigla]]="","",VLOOKUP(Tabela2[[#This Row],[sigla]],créditos_base!B:C,2,0)) -> JACQUELINE LIMA/ARQUIVO DA EDITORA | Z8: =Tabela2[[#This Row],[ilustrador]] -> JACQUELINE LIMA/ARQUIVO DA EDITORA | AA8: 4 | AB8: R: 18/06 ; R2: 18/06 ; F: 24/06 | AC8: PAGO | AD8: ="Plantar" -> Plantar | AE8: ="Educação Física" -> Educação Física
A9: i0506_3p012ef_g27_e002 | B9: APLICADA | C9: ILUSTRAÇÃO | D9: MP-E | F9: 3 | G9: 3 | I9: NOVA | O9: Ilustrações de saltos ornamentais. Não precisa ser a representação do corpo humano como está na ref., pode ser apenas um bonequinho mesmo. i0506A_3p012ef_g27_e002 Ilustrar sequência de ilustração técnica para representar o salto carpado. i0506B_3p012ef_g27_e002 Ilustrar sequência de ilustração técnica para representar o salto grupado. i0506C_3p012ef_g27_e002 Ilustrar sequência de ilustração técnica para representar o salto grupado. i0506D_3p012ef_g27_e002 Ref. para o salto acrobático; https://pt.wikihow.com/Dar-um-Salto-Mortal | Q9: 7 | R9: 45862 | S9: 45866 | T9: 45870 | U9: 45873 | V9: 45873 | W9: dz | X9: =IF(Tabela2[[#This Row],[sigla]]="","",VLOOKUP(Tabela2[[#This Row],[sigla]],créditos_base!B:C,2,0)) -> DANIEL GUSTAVO SILVA GONÇALVES/ARQUIVO DA EDITORA | Z9: =Tabela2[[#This Row],[ilustrador]] -> DANIEL GUSTAVO SILVA GONÇALVES/ARQUIVO DA EDITORA | AA9: 3 | AB9: R: 01/08 ; F: 04/08 | AC9: PAGO | AD9: ="Plantar" -> Plantar | AE9: ="Educação Física" -> Educação Física
A10: i0510_3p012ef_g27_e002 | B10: APLICADA | C10: ILUSTRAÇÃO | D10: MP-E | F10: 3 | G10: 3 | I10: NOVA | O10: Ilustrar o movimento dos giros e rotações (transversal, longitudinal e frontal), conforme consta abaixo. Não precisa separar as cenas, pode ser como está abaixo, e seguindo com a ideia dos bonequinhos, sem ser um corpo de ser humano mesmo. Fazer a primeira para representar a rotação transversal, a segunda para representar a longitudinal e a terceira para representar a frontal. Outra ref. para verificar as rotações: https://portalidea.com.br/cursos/bsico-de-ginstica-artstica-apostila04.pdf P. 247 – rotação transversal P. 246 – rotação longitudinal P. 242 – rotação anteroposterior/ rotação frontal | Q10: 7 | R10: 45862 | S10: 45866 | T10: 45870 | U10: 45873 | V10: 45873 | W10: dz | X10: =IF(Tabela2[[#This Row],[sigla]]="","",VLOOKUP(Tabela2[[#This Row],[sigla]],créditos_base!B:C,2,0)) -> DANIEL GUSTAVO SILVA GONÇALVES/ARQUIVO DA EDITORA | Z10: =Tabela2[[#This Row],[ilustrador]] -> DANIEL GUSTAVO SILVA GONÇALVES/ARQUIVO DA EDITORA | AA10: 4 | AB10: R: 01/08 ; F: 04/08 | AC10: PAGO | AD10: ="Plantar" -> Plantar | AE10: ="Educação Física" -> Educação Física
A11: i0701_3p012ef_g27_e002 | B11: PRONTA | C11: ILUSTRAÇÃO | D11: MP-E | F11: 3 | G11: 4 | I11: NOVA | O11: Ilustração de crianças brincando de roda pátio de descola. Elas devem estar de mãos dadas, em círculo. Ilustrar 5 crianças, ao menos, para que a roda fique num tamanho bom: Ilustra uma menina branca de cabelo preto gorda (precisa aparentar ser gorda) Um menino loiro com down Uma menina negra com o cabelo solto Uma menina parda com o cabelo preso Um menino negro | Q11: 8 | R11: 45869 | S11: 45869 | T11: 45873 | U11: 45875 | V11: 45876 | W11: lz | X11: =IF(Tabela2[[#This Row],[sigla]]="","",VLOOKUP(Tabela2[[#This Row],[sigla]],créditos_base!B:C,2,0)) -> RAFAEL LUZIO/ARQUIVO DA EDITORA | Z11: =Tabela2[[#This Row],[ilustrador]] -> RAFAEL LUZIO/ARQUIVO DA EDITORA | AA11: 3 | AB11: R: 04/08 ; F: 06/08 | AC11: PAGO | AD11: ="Plantar" -> Plantar | AE11: ="Educação Física" -> Educação Física
A12: i0707_1p012ef_g27_e002 | B12: PRONTA | C12: ILUSTRAÇÃO | D12: MP-E | E12: 79 | F12: 1 | G12: 4 | I12: NOVA | O12: ilustração da brincadeira acompanhe meus pés, Ilustrar 5 crianças sentadas em círculo que deverão estar de vendas nos olhos, no chão de um pátio de escola e outras duas no centro da roda. Variar biotipos e etnias: Uma menina morena de cabelo comprido liso, com traços étnicos indígenas; Uma menina morena de cabelo cacheado mais gordinha; Um menino loiro de óculos com grau bem forte; Dois meninos negros, um de maior estatura que a maioria da turma e outro mais baixinho; Um menino moreno/pardo No centro: um menino ruivo em cadeira de roda batendo palma e uma menina oriental imitando-o As crianças devem estar de uniforme escolar e deve ter um professor de Ed. Física próximo delas. A referência a seguir é só pra mostrar que as crianças do centro da roda devem estar fazendo o mesmo movimento | Q12: 4 | R12: 45832 | S12: 45840 | T12: 45841 | U12: 45842 | V12: 45847 | W12: dn | X12: =IF(Tabela2[[#This Row],[sigla]]="","",VLOOKUP(Tabela2[[#This Row],[sigla]],créditos_base!B:C,2,0)) -> GUILHERME RODRIGUES/ARQUIVO DA EDITORA | AA12: 4 | AB12: R: 03/07 ; F: 09/07 | AC12: PAGO | AD12: ="Plantar" -> Plantar | AE12: ="Educação Física" -> Educação Física
A13: i0901_3p012ef_g27_e002 | B13: ILUSTRANDO | C13: ILUSTRAÇÃO | D13: MP-E | F13: 3 | G13: 5 | I13: NOVA | O13: Arte, produzir ilustração do mini sumô: dois estudantes frente a frente dentro de um círculo com os joelhos flexionados, conforme exemplo abaixo. O ambiente deve aparentar ser uma quadra escolar. Fazer uma ilustração com característica mais técnicas, de modo que não precise ser identificado se é menino ou menina dentro do círculo, se for possível, fazer bonequinhos, assim como foi feito no jogo de bets i0301_3p012ef_g27_e002 | Q13: 9 | R13: 45873 | S13: 45874 | T13: 45875 | U13: 45878 | V13: 45881 | W13: dz | X13: =IF(Tabela2[[#This Row],[sigla]]="","",VLOOKUP(Tabela2[[#This Row],[sigla]],créditos_base!B:C,2,0)) -> DANIEL GUSTAVO SILVA GONÇALVES/ARQUIVO DA EDITORA | Z13: =Tabela2[[#This Row],[ilustrador]] -> DANIEL GUSTAVO SILVA GONÇALVES/ARQUIVO DA EDITORA | AA13: 6 | AB13: R: 06/08 ; F: 12/08 | AC13: PAGO | AD13: ="Plantar" -> Plantar | AE13: ="Educação Física" -> Educação Física
A14: i0902_3p012ef_g27_e002 | B14: ILUSTRANDO | C14: ILUSTRAÇÃO | D14: MP-E | F14: 3 | G14: 5 | I14: NOVA | O14: ARTE, ilustrar dois estudantes, também podem ser bonequinhos, como na il anterior na posição de cócoras, conforme exemplo abaixo. O ambiente deve aparentar ser uma quadra escolar. | Q14: 9 | R14: 45873 | S14: 45874 | T14: 45875 | U14: 45878 | V14: 45881 | W14: dz | X14: =IF(Tabela2[[#This Row],[sigla]]="","",VLOOKUP(Tabela2[[#This Row],[sigla]],créditos_base!B:C,2,0)) -> DANIEL GUSTAVO SILVA GONÇALVES/ARQUIVO DA EDITORA | Z14: =Tabela2[[#This Row],[ilustrador]] -> DANIEL GUSTAVO SILVA GONÇALVES/ARQUIVO DA EDITORA | AA14: 6 | AB14: R: 06/08 ; F: 11/08 | AC14: PAGO | AD14: ="Plantar" -> Plantar | AE14: ="Educação Física" -> Educação Física
A15: i0903_3p012ef_g27_e002 | B15: ILUSTRANDO | C15: ILUSTRAÇÃO | D15: MP-E | F15: 3 | G15: 5 | I15: NOVA | O15: ARTE, ilustrar dois estudantes dentro de um círculo, também podem ser bonequinhos, disputando a bola, conforme exemplo abaixo. O ambiente deve aparentar ser uma quadra escolar. | Q15: 9 | R15: 45873 | S15: 45874 | T15: 45875 | U15: 45878 | V15: 45881 | W15: dz | X15: =IF(Tabela2[[#This Row],[sigla]]="","",VLOOKUP(Tabela2[[#This Row],[sigla]],créditos_base!B:C,2,0)) -> DANIEL GUSTAVO SILVA GONÇALVES/ARQUIVO DA EDITORA | Z15: =Tabela2[[#This Row],[ilustrador]] -> DANIEL GUSTAVO SILVA GONÇALVES/ARQUIVO DA EDITORA | AA15: 6 | AB15: R: 06/08 ; F: 11/08 | AC15: PAGO | AD15: ="Plantar" -> Plantar | AE15: ="Educação Física" -> Educação Física
A16: i0904_3p012ef_g27_e002 | B16: ILUSTRANDO | C16: ILUSTRAÇÃO | D16: MP-E | F16: 3 | G16: 5 | I16: NOVA | O16: Arte, ilustrar dois estudantes sentados com os pés juntos conforme exemplo abaixo. Também pode seguir a ideia de bonequinhos. O ambiente deve aparentar ser uma quadra escolar. | Q16: 9 | R16: 45873 | S16: 45874 | T16: 45875 | U16: 45878 | V16: 45881 | W16: dz | X16: =IF(Tabela2[[#This Row],[sigla]]="","",VLOOKUP(Tabela2[[#This Row],[sigla]],créditos_base!B:C,2,0)) -> DANIEL GUSTAVO SILVA GONÇALVES/ARQUIVO DA EDITORA | Z16: =Tabela2[[#This Row],[ilustrador]] -> DANIEL GUSTAVO SILVA GONÇALVES/ARQUIVO DA EDITORA | AA16: 6 | AB16: R: 06/08 ; F: 11/08 | AC16: PAGO | AD16: ="Plantar" -> Plantar | AE16: ="Educação Física" -> Educação Física
A17: i6101_1p012ef_g27_e002 | B17: EDICAO_ARTE | C17: ILUSTRAÇÃO | D17: CAPA | E17: 1 | F17: 1 | G17: 1 | I17: NOVA | O17: ilustração da capa | S17: 45856 | T17: 45859 | U17: 45871 | V17: 45877 | W17: cv | X17: =IF(Tabela2[[#This Row],[sigla]]="","",VLOOKUP(Tabela2[[#This Row],[sigla]],créditos_base!B:C,2,0)) -> CLARISSA CABRAL/ARQUIVO DA EDITORA | Z17: =Tabela2[[#This Row],[ilustrador]] -> CLARISSA CABRAL/ARQUIVO DA EDITORA | AA17: 30 | AB17: F:7/8 | AC17: PAGO | AD17: ="Plantar" -> Plantar | AE17: ="Educação Física" -> Educação Física

Sheet créditos_base
A1: CRÉDITOS GERAIS DA FTD PARA REFERÊNCIA - EF1
A2: Nome do ilustrador | B2: Sigla Arte | C2: Crédito
A3: Acervo da editora | B3: xx | C3: ARQUIVO DA EDITORA
A4: Sigla ZZ (ver documento de ils. técnicas) | B4: zz | C4: VER DOCUMENTO DE ILS. TÉCNICAS
A5: ILUSTRAÇOES DE PROVAS OFICIAIS (somente se não houver crédito) | B5: yv | C5: NOME DO VESTIBULAR/DATA
A6: ILUSTRAÇÕES DE PLACAS DE TRÂNSITO | B6: yy | C6: DENATRAN/ARQUIVO DA EDITORA
A7: ILUSTRAÇÕES DE BANDEIRAS DE PAÍS | B7: yp | C7: NOME DO PAÍS/ARQUIVO DA EDITORA
A8: ILUSTRAÇÕES DE BANDEIRAS DE ESTADO | B8: ye | C8: NOME DO ESTADO/ARQUIVO DA EDITORA
A9: ILUSTRAÇÕES GERADAS POR PROGRAMAS C/ IA | B9: ia | C9: ARQUIVO DA EDITORA
A10: Arte | B10: a | C10: ARTE
A11: 3 Pixel Studio | B11: px | C11: ROBSON OLIVIERI/ARQUIVO DA EDITORA
A12: A7 Estudio | B12: ao | C12: JORGE RIBEIRO/ARQUIVO DA EDITORA
A13: Adilson Farias | B13: af | C13: ADILSON FARIAS/ARQUIVO DA EDITORA
... A40: Beatriz Mayumi | B40: bm | C40: BEATRIZ MAYUMI/ARQUIVO DA EDITORA
A41: Belli Studio Design | B41: bl
A42: Bernardo França | B42: be | C42: BERNARDO FRANÇA/ARQUIVO DA EDITORA
A43: Bianca Nazari | B43: bi | C43: BIANCA NAZARI/ARQUIVO DA EDITORA
A44: Brenda Bossato | B44: bd | C44: BRENDA BOSSATO/ARQUIVO DA EDITORA
A45: Brenda Goes | B45: bg | C45: BRENDA GOES/ARQUIVO DA EDITORA
A46: Bruna Campos | B46: bp | C46: BRUNA CAMPOS/ARQUIVO DA EDITORA
A47: Brunna Mancuso | B47: bs | C47: BRUNNA MANCUSO/ARQUIVO DA EDITORA
A48: Bruna Menezes | B48: bz | C48: BRUNA MENEZES/ARQUIVO DA EDITORA
A49: Bruno Badain | B49: bb | C49: BRUNO BADAIN/ARQUIVO DA EDITORA
A50: Bruno H. S. Cerkuenik | B50: bc | C50: BRUNO CERKUENIK/ARQUIVO DA EDITORA
A51: Bruno Nunes Coelho | B51: bn | C51: BRUNO NUNES/ARQUIVO DA EDITORA
A52: Bruno Oliveira Sampaio | B52: br | C52: BRUNO SAMPAIO/ARQUIVO DA EDITORA
A53: Bruno Rosal de Vasconcelos | B53: bu
A54: Caio Hideki Takaso Tanaka | B54: ct | C54: CAIO TANAKA/ARQUIVO DA EDITORA
A55: Cajila Barbosa | B55: kj | C55: CAJILA BARBOSA/ARQUIVO DA EDITORA
A56: Camila Ferreira Carmona | B56: ca | C56: CAMILA CARMONA/ARQUIVO DA EDITORA
A57: Carlitos Pinheiro | B57: cq | C57: CARLITOS PINHEIRO/ARQUIVO DA EDITORA
A58: Carlos Alberto Borin Junior | B58: cj | C58: CARLOS BORIN/ARQUIVO DA EDITORA
A59: Carlos Eduardo Nascimento | B59: cn | C59: CARLOS EDUARDO NASCIMENTO/ARQUIVO DA EDITORA
A60: Carmen Ferreira Martinez | B60: cc | C60: CARMEN MARTINEZ/ARQUIVO DA EDITORA
A61: Carol Rempto | B61: cw | C61: CAROL REMPTO/ARQUIVO DA EDITORA
A62: Carol Sartori | B62: cx | C62: CAROL SARTORI/ARQUIVO DA EDITORA
A63: Carolina Coroa | B63: kk | C63: CAROLINA COROA/ARQUIVO DA EDITORA
A64: Caroline Antunes e Silva | B64: cd | C64: CAROLINE ANTUNES E SILVA/ARQUIVO DA EDITORA
A65: Caroline Romão Bezerra | B65: co | C65: CAROLINE ROMÃO BEZERRA/ARQUIVO DA EDITORA
A66: Cartoon Pro | B66: cp
...

Sheet metadados
A1: PRÉ-EDIÇÃO | B1: ILUSTRAÇÃO | C1: CAPA | D1: 1 | E1: AJUSTE | F1: SCRIBA | G1: 1 | H1: PREVISAO
A2: EDICAO_EQUIPE | B2: IL TEC ARTE | C2: APRESENT. | D2: 2 | E2: NOVA | F2: FTD | G2: 2 | H2: FINALIZADO
A3: EDICAO_ARTE | B3: IL + FOTO | C3: SUMÁRIO | D3: 3 | E3: RESGATE | F3: MDN | G3: 3 | H3: FINALIZADO RAFE
A4: ILUSTRANDO | B4: MAPA | C4: ABERTURA | D4: 4 | F4: SABER | G4: 4 | H4: PAGO
A5: AVALIANDO | B5: GRÁFICO | C5: MIOLO | D5: 5 | F5: SM | G5: 5 | H5: PAGO RAFE
A6: AJUSTANDO | B6: LINHA TEMPO | C6: PAG.ESPECIAL | D6: 6 | F6: SCP | G6: 6
A7: FINALIZANDO | B7: INFOGRÁFICO | C7: MP-G | D7: ÚNICO | F7: ABR | G7: 7
A8: PRONTA | C8: MP-E | F8: BASE | G8: 8
A9: APLICADA | F9: IBEP | G9: 9
A10: EXCLUIDA | F10: LEYA | G10: 10
F11: SARAIVA | G11: 11
F12: SANTILLANA | G12: 12
F13: QUINTETO | G13: 13
G14: 14
G15: 30
G16: 31
