Workbook

Sheet ilustração
A1: retranca | B1: status | C1: categoria | D1: localizacao | E1: pagina | F1: volume | G1: unidade | H1: capitulo_secao | I1: tipo | J1: NOME DA OBRA PARA RESGATE | K1: PÁGINA PARA RESGATE | L1: VOLUME PARA RESGATE | M1: VERSÃO PARA RESGATE | N1: PROPRIEDADE | O1: descricao | P1: observacao_edit_nuc | Q1: lote | R1: data_liberacao_para_arte | S1: data_envio_pedido | T1: data_recebimento_rafe | U1: data_retorno_rafe | V1: data_recebimento_finalizada | W1: sigla | X1: ilustrador | Y1: ilustrador_ajuste | Z1: credito | AA1: classificacao | AB1: observacao_arte | AC1: pagamento | AD1: projeto | AE1: componente | AF1: ilustrador_resgate
A2: i0198zz_3p011m_g27_e001 | B2: APLICADA | C2: IL TEC ARTE | D2: MIOLO | E2: 25 | F2: 3 | G2: 1 | I2: AJUSTE | O2: Ilustração de uma tabela em folha de caderno (trocou o código, é a mesma da i01153p011m que foi excluída) | S2: 45860 | V2: 45860 | W2: zz | X2: =IF(Tabela2[[#This Row],[sigla]]="","",VLOOKUP(Tabela2[[#This Row],[sigla]],créditos_base!B:C,2,0)) -> VER DOCUMENTO DE ILS. TÉCNICAS | Y2: Arte | Z2: VINÍCIUS COSTA/ARQUIVO DA EDITORA | AA2: 13 | AB2: resgate com ajuste | AC2: FINALIZADO | AD2: ="Pitanguá" -> Pitanguá | AE2: ="Matemática" -> Matemática
A3: 1318_3p011m_g27_e001 | B3: APLICADA | C3: IL TEC ARTE | D3: MIOLO | E3: 137 | F3: 3 | G3: 7 | I3: RESGATE | O3: Resgatar ilustração de um short azul, da página 137 do g23_mdn_lt_3npm. Código antigo i1406rn_3pmm_g19_mdn | W3: rn | X3: =IF(Tabela2[[#This Row],[sigla]]="","",VLOOKUP(Tabela2[[#This Row],[sigla]],créditos_base!B:C,2,0)) -> RAFAEL L. GAION/ARQUIVO DA EDITORA | Z3: =Tabela2[[#This Row],[ilustrador]] -> RAFAEL L. GAION/ARQUIVO DA EDITORA | AD3: ="Pitanguá" -> Pitanguá | AE3: ="Matemática" -> Matemática
A4: g0104_3p011m_g27_e001 | B4: APLICADA | C4: GRÁFICO | D4: MIOLO | E4: 14 | F4: 3 | G4: 1 | I4: AJUSTE | O4: resgatar gráfico com a cor preferida dos estudantes do g23_mdn_lt_3npm_p014 código antigo gt0209sl_3pmm_g19_mdn AJUSTE: No gráfico, trocar "Quantidade de alunos" por "Quantidade de estudantes". Inserir fio contorno preto nas barras do grafico. | Q4: 78 | R4: 45820 | S4: 45825 | V4: 45826 | W4: sl | X4: =IF(Tabela2[[#This Row],[sigla]]="","",VLOOKUP(Tabela2[[#This Row],[sigla]],créditos_base!B:C,2,0)) -> SERGIO LIMA/ARQUIVO DA EDITORA | Y4: Rebecca Baniski | Z4: =Tabela2[[#This Row],[ilustrador]] -> SERGIO LIMA/ARQUIVO DA EDITORA | AA4: 13 | AB4: resgate com ajuste | AC4: FINALIZADO | AD4: ="Pitanguá" -> Pitanguá | AE4: ="Matemática" -> Matemática
A5: g0112_5p011m_g27_e001 | B5: APLICADA | C5: GRÁFICO | D5: MIOLO | E5: 22 | F5: 5 | G5: 1 | I5: AJUSTE | O5: Resgatar ilustração de um gráfico de personalidades brasileiras com barras horizontais. Veio de: g23_mdn_lt_5npm_p014. Código antigo: i0210ri_5pmm_g19_mdn AJUSTE: atualizar para novo padrão, compondo fio preto nas barras | Q5: 126 | R5: 45863 | S5: 45867 | V5: 45869 | W5: ri | X5: =IF(Tabela2[[#This Row],[sigla]]="","",VLOOKUP(Tabela2[[#This Row],[sigla]],créditos_base!B:C,2,0)) -> RONALDO LUCENA/ARQUIVO DA EDITORA | Y5: Arte | Z5: =Tabela2[[#This Row],[ilustrador]] -> RONALDO LUCENA/ARQUIVO DA EDITORA | AA5: 13 | AB5: RESGATE COM AJUSTAE | AC5: FINALIZADO | AD5: ="Pitanguá" -> Pitanguá | AE5: ="Matemática" -> Matemática
A6: g0116_3p011m_g27_e001 | B6: APLICADA | C6: GRÁFICO | D6: MIOLO | E6: 194 | F6: 3 | G6: 1 | I6: AJUSTE | O6: Resgatar gráfico/ilustração pesquisa dos estudantes; g23_mdn_lt_3npm_p194; código antigo gt3413sl_3npm_g23_mdn_aj AJUSTE. Trocara alunos para estudantes no eixo vertical e inserir fio contorno preto nas barras do grafico. | Q6: 78 | R6: 45820 | S6: 45831 | V6: 45831 | W6: sl | X6: =IF(Tabela2[[#This Row],[sigla]]="","",VLOOKUP(Tabela2[[#This Row],[sigla]],créditos_base!B:C,2,0)) -> SERGIO LIMA/ARQUIVO DA EDITORA | Y6: Ingridhi Borges | Z6: =Tabela2[[#This Row],[ilustrador]] -> SERGIO LIMA/ARQUIVO DA EDITORA | AA6: 13 | AB6: RESGATE COM AJUSTE | AC6: FINALIZADO | AD6: ="Pitanguá" -> Pitanguá | AE6: ="Matemática" -> Matemática
A7: g0118_3p011m_g27_e001 | B7: APLICADA | C7: GRÁFICO | D7: MIOLO | E7: 197 | F7: 3 | G7: 1 | I7: AJUSTE | O7: Resgatar gráfico/ilustração de moradores por quantidade de residências; g23_mdn_lt_3npm_p197; código antigo gt3415sl_3npm_g23_mdn_aj | Q7: 164 | R7: 45892 | S7: 45894 | V7: 45894 | W7: sl | X7: =IF(Tabela2[[#This Row],[sigla]]="","",VLOOKUP(Tabela2[[#This Row],[sigla]],créditos_base!B:C,2,0)) -> SERGIO LIMA/ARQUIVO DA EDITORA | Y7: Maryane Vioto Silva | Z7: =Tabela2[[#This Row],[ilustrador]] -> SERGIO LIMA/ARQUIVO DA EDITORA | AA7: 14 | AB7: Resgate com ajuste | AC7: FINALIZADO | AD7: ="Pitanguá" -> Pitanguá | AE7: ="Matemática" -> Matemática
A8: g0124_5p011m_g27_e001 | B8: APLICADA | C8: GRÁFICO | D8: MIOLO | E8: 30 | F8: 5 | G8: 1 | I8: NOVA | O8: Ilustração de parte de um gráfico de colunas verticais, como a ref. Nesse gráfico, os bairros devem ser A, B, C e D, porém deve-se compor apenas as barras de A e B. A barra de A deve representar 300 kg e a de B, 700 kg. A escala do eixo vertical deve ser graduada de 100 em 100, com início em 0 e fim em 1 000. O eixo vertical deve ser nomeado por “Quantidade (em kg)” e o horizontal, “Bairro”. O restante do gráfico será preenchido pelo estudante. | Q8: 126 | R8: 45863 | S8: 45867 | V8: 45869 | W8: ib | X8: =IF(Tabela2[[#This Row],[sigla]]="","",VLOOKUP(Tabela2[[#This Row],[sigla]],créditos_base!B:C,2,0)) -> INGRIDHI BORGES/ARQUIVO DA EDITORA | Y8: Arte | Z8: =Tabela2[[#This Row],[ilustrador]] -> INGRIDHI BORGES/ARQUIVO DA EDITORA | AA8: 13 | AB8: PADRAO | AC8: FINALIZADO | AD8: ="Pitanguá" -> Pitanguá | AE8: ="Matemática" -> Matemática
A9: g0125_2p011m_g27_e001 | B9: APLICADA | C9: GRÁFICO | D9: MIOLO | F9: 2 | G9: 1 | H9: 1 | I9: AJUSTE | O9: Resgatar e ajustar gráfico sobre Filhotes que aparecem nas fotos, da página 134 do g23_mdn_lt_2npm_p128a135_u6; código antigo gt1206_2pmm_g19_mdn Ajuste: retirar barras em cor resposta | Q9: 13 | R9: 45743 | S9: 45743 | V9: 45743 | W9: sl | X9: =IF(Tabela2[[#This Row],[sigla]]="","",VLOOKUP(Tabela2[[#This Row],[sigla]],créditos_base!B:C,2,0)) -> SERGIO LIMA/ARQUIVO DA EDITORA | Y9: Tatiane Galheiro | Z9: =Tabela2[[#This Row],[ilustrador]] -> SERGIO LIMA/ARQUIVO DA EDITORA | AA9: 13 | AB9: Resgate com ajuste | AC9: FINALIZADO | AD9: ="Pitanguá" -> Pitanguá | AE9: ="Matemática" -> Matemática
A10: g0146_3p011m_g27_e001 | B10: APLICADA | C10: ILUSTRAÇÃO | D10: MIOLO | E10: 41 | F10: 3 | G10: 1 | I10: AJUSTE | O10: Resgatar gráfico/ilustração necessidade de horas de sono; g23_mdn_lt_3npm_p196; código antigo gt3409sl_3npm_g23_mdn_ef_aj AJUSTE: Retirar as barras em cor resposta | Q10: 78 | R10: 45820 | S10: 45825 | V10: 45826 | W10: sl | X10: =IF(Tabela2[[#This Row],[sigla]]="","",VLOOKUP(Tabela2[[#This Row],[sigla]],créditos_base!B:C,2,0)) -> SERGIO LIMA/ARQUIVO DA EDITORA | Y10: Rebecca Baniski | Z10: =Tabela2[[#This Row],[ilustrador]] -> SERGIO LIMA/ARQUIVO DA EDITORA | AA10: 13 | AB10: resgate com ajuste | AC10: FINALIZADO | AD10: ="Pitanguá" -> Pitanguá | AE10: ="Matemática" -> Matemática
A11: g0146_4p011m_g27_e001 | B11: APLICADA | C11: IL TEC ARTE | D11: MIOLO | E11: xx | F11: 4 | G11: 1 | I11: AJUSTE | O11: Resgatar gráfico de valores gastos e arrecadados. Veio de: g23_mdn_lt_4npm_p67 Código antigo: gt0806_4pmm_g19_mdn | Q11: 181 | R11: 45906 | S11: 45908 | V11: 45908 | W11: sl | X11: =IF(Tabela2[[#This Row],[sigla]]="","",VLOOKUP(Tabela2[[#This Row],[sigla]],créditos_base!B:C,2,0)) -> SERGIO LIMA/ARQUIVO DA EDITORA | Y11: Tamires Azevedo | Z11: =Tabela2[[#This Row],[ilustrador]] -> SERGIO LIMA/ARQUIVO DA EDITORA | AA11: 13 | AB11: ajuste de arte | AC11: FINALIZADO | AD11: ="Pitanguá" -> Pitanguá | AE11: ="Matemática" -> Matemática
A12: g0147_4p011m_g27_e001 | B12: EXCLUIDA | C12: IL TEC ARTE | D12: MIOLO | E12: xx | F12: 4 | G12: 1 | I12: RESGATE | O12: Resgatar gráfico de tempo por nome. Veio de: g23_mdn_lt_4npm_p068. Código antigo: gt0807_4pmm_g19_mdn | W12: sl | X12: =IF(Tabela2[[#This Row],[sigla]]="","",VLOOKUP(Tabela2[[#This Row],[sigla]],créditos_base!B:C,2,0)) -> SERGIO LIMA/ARQUIVO DA EDITORA | Z12: =Tabela2[[#This Row],[ilustrador]] -> SERGIO LIMA/ARQUIVO DA EDITORA | AD12: ="Pitanguá" -> Pitanguá | AE12: ="Matemática" -> Matemática
A13: g0148_4p011m_g27_e001 | B13: EXCLUIDA | C13: IL TEC ARTE | D13: MIOLO | E13: xx | F13: 4 | G13: 1 | I13: RESGATE | O13: Resgatar ilustração de um gráfico de barras tempo por nome. Veio de: g23_mdn_lt_4npm_p068. Código antigo: i1405ri_4npm_g23_mdn_aj | W13: ri | X13: =IF(Tabela2[[#This Row],[sigla]]="","",VLOOKUP(Tabela2[[#This Row],[sigla]],créditos_base!B:C,2,0)) -> RONALDO LUCENA/ARQUIVO DA EDITORA | Z13: =Tabela2[[#This Row],[ilustrador]] -> RONALDO LUCENA/ARQUIVO DA EDITORA | AD13: ="Pitanguá" -> Pitanguá | AE13: ="Matemática" -> Matemática
A14: g0151_3p011m_g27_e001 | B14: APLICADA | C14: ILUSTRAÇÃO | D14: MIOLO | E14: 47 | F14: 3 | G14: 1 | I14: AJUSTE | O14: Resgatar gráfico/ilustração quantidade de prefeitas eleitas por ano; g23_mdn_lt_3npm_p199; código antigo gt3411sl_3npm_g23_mdn_aj AJUSTE: O novo gráfico deve ir de 2004 a 2024 e representar os seguintes dados: 2004: 406 prefeitas eleitas 2008: 498 prefeitas eleitas 2012: 654 prefeitas eleitas 2016: 635 prefeitas eleitas 2020: 656 prefeitas eleitas 2024: 729 prefeitas eleitas Inserir fio contorno preto nas barras. | Q14: 78 | R14: 45820 | S14: 45828 | V14: 45831 | W14: sl | X14: =IF(Tabela2[[#This Row],[sigla]]="","",VLOOKUP(Tabela2[[#This Row],[sigla]],créditos_base!B:C,2,0)) -> SERGIO LIMA/ARQUIVO DA EDITORA | Y14: Ingridhi Borges | Z14: =Tabela2[[#This Row],[ilustrador]] -> SERGIO LIMA/ARQUIVO DA EDITORA | AA14: 13 | AB14: RESGATE COM AJUSTE | AC14: FINALIZADO | AD14: ="Pitanguá" -> Pitanguá | AE14: ="Matemática" -> Matemática
A15: g0153_4p011m_g27_e001 | B15: APLICADA | C15: GRÁFICO | D15: MIOLO | E15: 35 | F15: 4 | G15: 1 | I15: AJUSTE | O15: Resgatar e ajustar ilustração gráfico de barras verticais altitude de montanhas; g23_mdn_lt_4npm_p22; código antigo gt0217sl_4npm_g23_mdn_aj AJUSTE: O ajuste consiste em trocar "McKinley" por "Denali" e atualizar os dados das barras e alturas das barras conforme novo valor, com as seguintes informações: - Everest: 8 848 - Monte Branco: 4 808 - Denali: 6 194 - Pico da Neblina: 2 994 Além disso, mudar o nome do eixo vertical para "Medida da altitude (em metros)". | Q15: 91 | R15: 45840 | S15: 45849 | V15: 45850 | W15: sl | X15: =IF(Tabela2[[#This Row],[sigla]]="","",VLOOKUP(Tabela2[[#This Row],[sigla]],créditos_base!B:C,2,0)) -> SERGIO LIMA/ARQUIVO DA EDITORA | Y15: Maryane Vioto Silva | Z15: =Tabela2[[#This Row],[ilustrador]] -> SERGIO LIMA/ARQUIVO DA EDITORA | AA15: 14 | AB15: Resgate com ajuste | AC15: FINALIZADO | AD15: ="Pitanguá" -> Pitanguá | AE15: ="Matemática" -> Matemática
A16: g0160_2p011m_g27_e001 | B16: APLICADA | C16: GRÁFICO | D16: MIOLO | F16: 2 | G16: 1 | I16: AJUSTE | O16: Resgatar e ajustar gráfico com a Quantidade de bolinhas colocadas na caixa, da página 143 do g23_mdn_lt_2npm_p136a143_u6; código antigo gt2226km_2npm_g23_mdn AJUSTE 1: Ajustar o texto para CxAA e ajustar o gráfico para um gráfico na vertical. Além disso, após ajustar o gráfico na vertical, retirar os fios verticais e manter apenas os fios horizontais, ficando as barras por cima dos fios. AJUSTE 2: Ajustar também a cor das barras. Deixar uma única cor, diferente de roxo e azul. Aumentar também a quantidade de bolinhas correspondente a cor Roxa, devem ser 25 bolinhas. Se necessário, ajustar a escala do gráfico para fechar a página. | Q16: 52 | R16: 45803 | S16: 45805 | V16: 45805 | W16: km | X16: =IF(Tabela2[[#This Row],[sigla]]="","",VLOOKUP(Tabela2[[#This Row],[sigla]],créditos_base!B:C,2,0)) -> KEITHY MOSTACHI/ARQUIVO DA EDITORA | Y16: Vinícius Costa | Z16: =Tabela2[[#This Row],[ilustrador]] -> KEITHY MOSTACHI/ARQUIVO DA EDITORA | AA16: 14 | AB16: Resgate com ajuste | AC16: FINALIZADO | AD16: ="Pitanguá" -> Pitanguá | AE16: ="Matemática" -> Matemática
A17: g0161_2p011m_g27_e001 | B17: APLICADA | C17: GRÁFICO | D17: MIOLO | F17: 2 | G17: 1 | I17: AJUSTE | O17: Resgatar e ajustar gráfico sobre Quantidade de copos de suco vendidos no dia 15 de outubro de 2022, de acordo com o sabor, da página 135 do g23_mdn_lt_2npm_p128a135_u6; código antigo gt2218_2npm_g23_mdn_re. AJUSTE: Ajustar o texto do gráfico para que fique em CxAA. Além disso, retirar os fios horizontais do gráfico e não separar as barras em quadradinhos, ficando as barras por cima dos fios. | Q17: 52 | R17: 45803 | S17: 45805 | V17: 45805 | W17: sl | X17: =IF(Tabela2[[#This Row],[sigla]]="","",VLOOKUP(Tabela2[[#This Row],[sigla]],créditos_base!B:C,2,0)) -> SERGIO LIMA/ARQUIVO DA EDITORA | Y17: Vinícius Costa | Z17: =Tabela2[[#This Row],[ilustrador]] -> SERGIO LIMA/ARQUIVO DA EDITORA | AA17: 14 | AB17: Resgate com ajuste | AC17: FINALIZADO | AD17: ="Pitanguá" -> Pitanguá | AE17: ="Matemática" -> Matemática
A18: g0163_2p011m_g27_e001 | B18: APLICADA | C18: GRÁFICO | D18: MIOLO | F18: 2 | G18: 1 | I18: AJUSTE | O18: Resgatar e ajustar gráfico com a Quantidade de gols marcados por alguns jogadores do campeonato de futebol da escola, em 2022, da página 138 do g23_mdn_lt_2npm_p136a143_u6; código antigo gt1210_2pmm_g19_mdn. AJUSTE: Ajustar texto do gráfico em CxAA, e retirar as linhas para o estudante completar. No lugar delas entrará com nomes visíveis para o estudante. Na primeira coluna terá o nome "MÁRCIO.", na segunda "CAIO.", na terceira "JÚLIO." e na quarta "FABRÍCIO", conforme referência a seguir. | Q18: 52 | R18: 45803 | S18: 45805 | V18: 45805 | W18: sl | X18: =IF(Tabela2[[#This Row],[sigla]]="","",VLOOKUP(Tabela2[[#This Row],[sigla]],créditos_base!B:C,2,0)) -> SERGIO LIMA/ARQUIVO DA EDITORA | Y18: Vinícius Costa | Z18: =Tabela2[[#This Row],[ilustrador]] -> SERGIO LIMA/ARQUIVO DA EDITORA | AA18: 14 | AB18: Resgate com ajuste | AC18: FINALIZADO | AD18: ="Pitanguá" -> Pitanguá | AE18: ="Matemática" -> Matemática
A19: g0164_4p011m_g27_e001 | B19: APLICADA | C19: GRÁFICO | D19: MIOLO | E19: 30 | F19: 4 | G19: 1 | I19: NOVA | O19: Ilustração de um pictograma para representar os dados do quadro a seguir. Tipo de animal Quantidade de razão (em kg) Búfalo 1 700 Porco 1 300 Galinha 1 100 O elemento pictórico deve ser sacas de ração. Nesse pictograma, cada saca deve representar 100 kg. Assim, na barra dos búfalos devem aparecer 17 sacas, dos porcos, 13, e das galinhas, 11. | Q19: 91 | R19: 45840 | S19: 45849 | V19: 45853 | W19: rm | X19: =IF(Tabela2[[#This Row],[sigla]]="","",VLOOKUP(Tabela2[[#This Row],[sigla]],créditos_base!B:C,2,0)) -> HELOÍSA PINTARELLI/ARQUIVO DA EDITORA | Z19: =Tabela2[[#This Row],[ilustrador]] -> HELOÍSA PINTARELLI/ARQUIVO DA EDITORA | AA19: 11 | AB19: FINALIZADA 16/07 | AC19: PAGO | AD19: ="Pitanguá" -> Pitanguá | AE19: ="Matemática" -> Matemática
A20: g0189_3p011m_g27_e001 | B20: APLICADA | C20: ILUSTRAÇÃO | D20: MIOLO | E20: 43 | F20: 3 | G20: 1 | I20: NOVA | O20: ilustração de gráfico de barras verticais com o eixo horizontal “Município” e o eixo vertical “Quantidade de pessoas. Esse gráfico de barras terá os seguintes dados: Altônia: 720 pessoas; Barbosa Ferraz: 462 pessoas; Carambeí: 770 pessoas; Engenheiro Beltrão: 641 pessoas; Iporã: 970 pessoas; Loanda: 766 pessoas. | Q20: 78 | R20: 45820 | S20: 45825 | V20: 45826 | W20: bk | X20: =IF(Tabela2[[#This Row],[sigla]]="","",VLOOKUP(Tabela2[[#This Row],[sigla]],créditos_base!B:C,2,0)) -> REBECCA BANISKI/ARQUIVO DA EDITORA | Z20: =Tabela2[[#This Row],[ilustrador]] -> REBECCA BANISKI/ARQUIVO DA EDITORA | AA20: 12 | AB20: Arte | AC20: FINALIZADO | AD20: ="Pitanguá" -> Pitanguá | AE20: ="Matemática" -> Matemática
A21: g0327_1p011m_g27_e001 | B21: APLICADA | C21: GRÁFICO | D21: MIOLO | E21: 52 | F21: 1 | G21: 2 | I21: NOVA | O21: Il. de gráfico de barras verticais com os eixos “QUANTIDADE DE CACHORROS” e “FOTO”. No eixo horizontal deve estar a indicação para cada coluna: FOTO 1; FOTO 2; FOTO 3; FOTO 4. Cada coluna deve ter uma barra com 7 quadradinhos cada. ARTE: usar a base da il gt4022sl_1bam_g23_ftd pegar essa só de exemplo para compor o gráfico, deixar os espaços mais quadradinhos e não tão retangulares, fazer conforme a referência. | Q21: 8 | R21: 45733 | S21: 45734 | V21: 45734 | W21: fg | X21: =IF(Tabela2[[#This Row],[sigla]]="","",VLOOKUP(Tabela2[[#This Row],[sigla]],créditos_base!B:C,2,0)) -> FELIPE GRIGOLI/ARQUIVO DA EDITORA | Y21: Arte | Z21: =Tabela2[[#This Row],[ilustrador]] -> FELIPE GRIGOLI/ARQUIVO DA EDITORA | AA21: 12 | AB21: PADRÃO | AC21: FINALIZADO | AD21: ="Pitanguá" -> Pitanguá | AE21: ="Matemática" -> Matemática
A22: g0508_5p011m_g27_e001 | B22: APLICADA | C22: GRÁFICO | D22: MIOLO | E22: 52 | F22: 5 | G22: 3 | I22: AJUSTE | O22: Resgatar gráfico do esporte preferido de estudantes da página 100 do g23_mdn_lt_5npm_p096a103_u5. Código antigo gt1005_5pmm_g19_mdn AJUSTE 1: Trocar nome do eixo "Quantidade de alunos" para "Quantidade de estudantes". AJUSTE 2: Além disso, tirar as linhas horizontais e verticais do gráfico, ou seja, deixá-lo com o fundo branco. | Q22: 55 | R22: 45803 | S22: 45810 | V22: 45810 | W22: ri | X22: =IF(Tabela2[[#This Row],[sigla]]="","",VLOOKUP(Tabela2[[#This Row],[sigla]],créditos_base!B:C,2,0)) -> RONALDO LUCENA/ARQUIVO DA EDITORA | Y22: Rebecca Baniski | Z22: =Tabela2[[#This Row],[ilustrador]] -> RONALDO LUCENA/ARQUIVO DA EDITORA | AB22: resgate com ajuste | AC22: FINALIZADO | AD22: ="Pitanguá" -> Pitanguá | AE22: ="Matemática" -> Matemática
A23: g0509_5p011m_g27_e001 | B23: APLICADA | C23: GRÁFICO | D23: MIOLO | E23: 54 | F23: 5 | G23: 3 | I23: AJUSTE | O23: Resgatar gráfico da quantidade de meninos e meninas, escrita em letras cursivas da página 102 do g23_mdn_lt_5npm_p096a103_u5. Código antigo gt1805ri_5npm_g23_mdn_aj. AJUSTE: atualizar ano para 2027 | Q23: 55 | R23: 45803 | S23: 45810 | V23: 45810 | W23: ri | X23: =IF(Tabela2[[#This Row],[sigla]]="","",VLOOKUP(Tabela2[[#This Row],[sigla]],créditos_base!B:C,2,0)) -> RONALDO LUCENA/ARQUIVO DA EDITORA | Y23: Rebecca Baniski | Z23: =Tabela2[[#This Row],[ilustrador]] -> RONALDO LUCENA/ARQUIVO DA EDITORA | AB23: resgate com ajuste | AC23: FINALIZADO | AD23: ="Pitanguá" -> Pitanguá | AE23: ="Matemática" -> Matemática
A24: g0511_5p011m_g27_e001 | B24: APLICADA | C24: GRÁFICO | D24: MIOLO | E24: 58 | F24: 5 | G24: 3 | I24: RESGATE | O24: Resgatar gráfico/pictograma de preferência de sabor de suco da página 104 do g23_mdn_lt_5npm_p104a111_u5. Código antigo gt1807ri_5npm_g23_mdn_aj | W24: ri | X24: =IF(Tabela2[[#This Row],[sigla]]="","",VLOOKUP(Tabela2[[#This Row],[sigla]],créditos_base!B:C,2,0)) -> RONALDO LUCENA/ARQUIVO DA EDITORA | Z24: =Tabela2[[#This Row],[ilustrador]] -> RONALDO LUCENA/ARQUIVO DA EDITORA | AD24: ="Pitanguá" -> Pitanguá | AE24: ="Matemática" -> Matemática
A25: g0512_5p011m_g27_e001 | B25: APLICADA | C25: GRÁFICO | D25: MIOLO | E25: 59 | F25: 5 | G25: 3 | I25: AJUSTE | O25: Resgatar gráfico de medalhas conquistadas por alguns países da página 105 do g23_mdn_lt_5npm_p104a111_u5. Código antigo gt1009_5pmm_g19_mdn AJUSTE 1: retirar textos em cor resposta AJUSTE 2: Ajustar tamanho das barras e atualizar os valores. De cima para baixo, as barras devem indicar, respectivamente, 53, 20, 91, 126, 32, 64, 40, 11. | Q25: 55 | R25: 45803 | S25: 45810 | V25: 45810 | W25: ri | X25: =IF(Tabela2[[#This Row],[sigla]]="","",VLOOKUP(Tabela2[[#This Row],[sigla]],créditos_base!B:C,2,0)) -> RONALDO LUCENA/ARQUIVO DA EDITORA | Y25: Rebecca Baniski | Z25: =Tabela2[[#This Row],[ilustrador]] -> RONALDO LUCENA/ARQUIVO DA EDITORA | AB25: resgate com ajuste | AC25: FINALIZADO | AD25: ="Pitanguá" -> Pitanguá | AE25: ="Matemática" -> Matemática
A26: g0513_5p011m_g27_e001 | B26: APLICADA | C26: GRÁFICO | D26: MIOLO | E26: 60 | F26: 5 | G26: 3 | I26: AJUSTE | O26: Resgatar o gráfico de despesa mensal com energia elétrica da página 106 do g23_mdn_lt_5npm_p104a111_u5. Código antigo gt1036_5pmm_g19_mdn | Q26: 200 | R26: 45923 | S26: 45923 | V26: 45923 | W26: sl | X26: =IF(Tabela2[[#This Row],[sigla]]="","",VLOOKUP(Tabela2[[#This Row],[sigla]],créditos_base!B:C,2,0)) -> SERGIO LIMA/ARQUIVO DA EDITORA | Y26: Vinícius Costa | Z26: =Tabela2[[#This Row],[ilustrador]] -> SERGIO LIMA/ARQUIVO DA EDITORA | AA26: 13 | AC26: FINALIZADO | AD26: ="Pitanguá" -> Pitanguá | AE26: ="Matemática" -> Matemática
A27: g0522_4p011m_g27_e001 | B27: APLICADA | C27: GRÁFICO | D27: MIOLO | E27: 67 | F27: 4 | G27: 3 | I27: AJUSTE | O27: Resgatar gráfico de dispositivo mais usado. Veio de: g23_mdn_lt_4npm_p073. Código antigo: gt1411ri_4npm_g23_mdn_aj AJUSTE: Mudar nome do eixo vertical, deve ser: Quantidade de estudantes e ajustar valores (consequentemente a escala do eixo vertical). Os novos valores são: Smartphone: 1 190 Tablet: 1 075 Notebook: 1 125 Computador de mesa: 1 110 | Q27: 97 | R27: 45845 | S27: 45852 | V27: 45861 | W27: ri | X27: =IF(Tabela2[[#This Row],[sigla]]="","",VLOOKUP(Tabela2[[#This Row],[sigla]],créditos_base!B:C,2,0)) -> RONALDO LUCENA/ARQUIVO DA EDITORA | Y27: Maryane Vioto Silva | Z27: =Tabela2[[#This Row],[ilustrador]] -> RONALDO LUCENA/ARQUIVO DA EDITORA | AA27: 13 | AB27: Resgate com ajuste | AC27: FINALIZADO | AD27: ="Pitanguá" -> Pitanguá | AE27: ="Matemática" -> Matemática
A28: g0523_5p011m_g27_e001 | B28: APLICADA | C28: GRÁFICO | D28: MIOLO | E28: 72 | F28: 5 | G28: 3 | I28: AJUSTE | O28: Resgatar gráfico/ilustração quantidade de estudantes de cinco turmas da escola; g23_mdn_lt_5npm_p54. Código antigo: gt0619_5pmm_g19_mdn AJUSTE: Trocar "Quantidade de alunos" por "Quantidade de estudantes". Compor fio preto em torno da barras de acordo com padrão. | Q28: 135 | R28: 45866 | S28: 45877 | V28: 45877 | W28: ri | X28: =IF(Tabela2[[#This Row],[sigla]]="","",VLOOKUP(Tabela2[[#This Row],[sigla]],créditos_base!B:C,2,0)) -> RONALDO LUCENA/ARQUIVO DA EDITORA | Y28: Gabriella Imai | Z28: =Tabela2[[#This Row],[ilustrador]] -> RONALDO LUCENA/ARQUIVO DA EDITORA | AA28: 13 | AB28: resgate com ajuste | AC28: FINALIZADO | AD28: ="Pitanguá" -> Pitanguá | AE28: ="Matemática" -> Matemática
A29: g0529_5p011m_g27_e001 | B29: APLICADA | C29: GRÁFICO | D29: MIOLO | E29: 56 | F29: 5 | G29: 3 | I29: NOVA | O29: Compor gráfico de colunas verticais para representar os dados do quadro a seguir. Frutas Quantidade de colegas Maçã 8 Banana 13 Laranja 9 Melancia 6 Kiwi 3 Além disso, compor título e fonte de pesquisa. São eles: Título: “Fruta preferida pelos colegas de Fabrício, em 18 de março de 2026”; Fonte de pesquisa: “Fonte de pesquisa: Anotações de Fabrício”. OBS: TODAS as informações que aparecem nessa il. devem ser feitas manuscritas e em letra cursiva. O gráfico deve ser ilustrado como se tivesse sido feito por uma pessoa. | Q29: 135 | R29: 45866 | S29: 45874 | V29: 45877 | W29: rm | X29: =IF(Tabela2[[#This Row],[sigla]]="","",VLOOKUP(Tabela2[[#This Row],[sigla]],créditos_base!B:C,2,0)) -> HELOÍSA PINTARELLI/ARQUIVO DA EDITORA | Z29: =Tabela2[[#This Row],[ilustrador]] -> HELOÍSA PINTARELLI/ARQUIVO DA EDITORA | AA29: 11 | AB29: FINALIZADA: 07/08 | AC29: PAGO | AD29: ="Pitanguá" -> Pitanguá | AE29: ="Matemática" -> Matemática
A30: g0531_2p011m_g27_e001 | B30: APLICADA | C30: GRÁFICO | D30: MIOLO | E30: 92 | F30: 2 | G30: 3 | I30: AJUSTE | O30: Resgatar gráfico sobre Brinquedos vendidos no dia 4 de julho de 2022, da página 133 do g23_mdn_lt_2npm_p128a135_u6; código antigo gt2217_2npm_g23_mdn_re AJUSTE: inserir até o número 13 no eixo “Quantidade vendida” e ajustar o gráfico para 10 bolas de futebol, 5 bonecas, 12 pipas e 4 ursos de pelúcia e deixar todo o texto em caixa alta alta. | Q30: 64 | R30: 45810 | S30: 45811 | V30: 45811 | W30: sl | X30: =IF(Tabela2[[#This Row],[sigla]]="","",VLOOKUP(Tabela2[[#This Row],[sigla]],créditos_base!B:C,2,0)) -> SERGIO LIMA/ARQUIVO DA EDITORA | Y30: Tamires Azevedo | Z30: =Tabela2[[#This Row],[ilustrador]] -> SERGIO LIMA/ARQUIVO DA EDITORA | AA30: 13 | AB30: Ajuste de arte | AC30: FINALIZADO | AD30: ="Pitanguá" -> Pitanguá | AE30: ="Matemática" -> Matemática
A31: g0532_4p011m_g27_e001 | B31: PRONTA | C31: GRÁFICO | D31: MIOLO | E31: xx | F31: 4 | G31: 2 | I31: RESGATE | O31: Resgatar ilustração de gráfico de quantidade de picolés. Veio de: g23_mdn_lt_4npm_p065. Código antigo: i1403ri_4npm_g23_mdn_aj | W31: ri | X31: =IF(Tabela2[[#This Row],[sigla]]="","",VLOOKUP(Tabela2[[#This Row],[sigla]],créditos_base!B:C,2,0)) -> RONALDO LUCENA/ARQUIVO DA EDITORA | Z31: =Tabela2[[#This Row],[ilustrador]] -> RONALDO LUCENA/ARQUIVO DA EDITORA | AD31: ="Pitanguá" -> Pitanguá | AE31: ="Matemática" -> Matemática
A32: g0534_4p011m_g27_e001 | B32: PRONTA | C32: GRÁFICO | D32: MIOLO | E32: xx | F32: 4 | G32: 2 | I32: RESGATE | O32: Resgatar gráfico de público do cinema. Veio de: g23_mdn_lt_4npm_p075. Código antigo: gt2501_4npm_m20_mdn | X32: =IF(Tabela2[[#This Row],[sigla]]="","",VLOOKUP(Tabela2[[#This Row],[sigla]],créditos_base!B:C,2,0)) | Z32: =Tabela2[[#This Row],[ilustrador]] | AD32: ="Pitanguá" -> Pitanguá | AE32: ="Matemática" -> Matemática
A33: g0535_3p011m_g27_e001 | B33: EXCLUIDA | C33: GRÁFICO | D33: MIOLO | E33: 195 | F33: 3 | G33: 3 | I33: RESGATE | O33: Resgatar ilustração gráfico pesquisa dos estudantes aniversários; g23_mdn_lt_3npm_p195; código antigo gt3414sl_3npm_g23_mdn_aj | P33: Excluída pela equipe. | W33: sl | X33: =IF(Tabela2[[#This Row],[sigla]]="","",VLOOKUP(Tabela2[[#This Row],[sigla]],créditos_base!B:C,2,0)) -> SERGIO LIMA/ARQUIVO DA EDITORA | Z33: =Tabela2[[#This Row],[ilustrador]] -> SERGIO LIMA/ARQUIVO DA EDITORA | AD33: ="Pitanguá" -> Pitanguá | AE33: ="Matemática" -> Matemática
A34: g0554_3p011m_g27_e001 | B34: APLICADA | C34: GRÁFICO | D34: MIOLO | E34: 91 | F34: 3 | G34: 3 | I34: NOVA | O34: Ilustração de um gráfico de barras horizontais no padrão da obra. Esse gráfico deve representar as informações do quadro a seguir. Fazer nesse padrão, porém sendo barras horizontais. | Q34: 43 | R34: 45790 | S34: 45790 | V34: 45791 | W34: rm | X34: =IF(Tabela2[[#This Row],[sigla]]="","",VLOOKUP(Tabela2[[#This Row],[sigla]],créditos_base!B:C,2,0)) -> HELOÍSA PINTARELLI/ARQUIVO DA EDITORA | Z34: =Tabela2[[#This Row],[ilustrador]] -> HELOÍSA PINTARELLI/ARQUIVO DA EDITORA | AA34: 12 | AB34: F: 15/05 | AC34: PAGO | AD34: ="Pitanguá" -> Pitanguá | AE34: ="Matemática" -> Matemática
A35: g0555_4p011m_g27_e001 | B35: APLICADA | C35: GRÁFICO | D35: MIOLO | E35: 62 | F35: 4 | G35: 3 | I35: NOVA | O35: Compor gráfico de barras verticais para representar os dados do quadro a seguir. Posto de coleta Quantidade (em quilogramas) A 1 210 B 1 190 C 1 260 D 1 120 No gráfico, A, B, C e D devem estar em bold. | Q35: 97 | R35: 45845 | S35: 45852 | V35: 45861 | W35: mv | X35: =IF(Tabela2[[#This Row],[sigla]]="","",VLOOKUP(Tabela2[[#This Row],[sigla]],créditos_base!B:C,2,0)) -> MARYANE VIOTO SILVA/ARQUIVO DA EDITORA | Z35: =Tabela2[[#This Row],[ilustrador]] -> MARYANE VIOTO SILVA/ARQUIVO DA EDITORA | AA35: 12 | AB35: Arte | AC35: FINALIZADO | AD35: ="Pitanguá" -> Pitanguá | AE35: ="Matemática" -> Matemática
A36: g0716_3p011m_g27_e001 | B36: APLICADA | C36: GRÁFICO | D36: MIOLO | E36: 105 | F36: 3 | G36: 4 | I36: AJUSTE | O36: Resgatar e ajustar gráfico sobre pesquisa sobre o uso do computador no dia a dia dos estudantes, da página 69 do g23_mdn_lt_3npm_p064a069_u3. Código antigo i0621rm_3pmm_g19_mdn AJUSTE: Adicionar eixo faltante (horizontal) e os nomes do eixo. O nome do eixo horizontal será "Quantidade de estudantes" e o eixo vertical será "Frequência de uso" AJUSTE: inserir eixo horizontal e os nomes do eixo. O nome do eixo horizontal será "Quantidade de estudantes" e o eixo vertical será "Frequência de uso". No eixo horizontal, deixar a escala de 3 em 3. Aproximar os bonequinhos do eixo vertical e retirar o fundo cor que está embaixo dos bonequinhos. Ver referência a seguir. | Q36: 48 | R36: 45797 | S36: 45797 | V36: 45798 | W36: rm | X36: =IF(Tabela2[[#This Row],[sigla]]="","",VLOOKUP(Tabela2[[#This Row],[sigla]],créditos_base!B:C,2,0)) -> HELOÍSA PINTARELLI/ARQUIVO DA EDITORA | Y36: Bruna Campos | Z36: =Tabela2[[#This Row],[ilustrador]] -> HELOÍSA PINTARELLI/ARQUIVO DA EDITORA | AA36: 13 | AB36: Resgate com ajuste | AC36: FINALIZADO | AD36: ="Pitanguá" -> Pitanguá | AE36: ="Matemática" -> Matemática
A37: g0725_1p011m_g27_e001 | B37: APLICADA | C37: GRÁFICO | D37: MIOLO | E37: 113 | F37: 1 | G37: 4 | I37: NOVA | O37: Ilustração de gráfico de barras com eixo vertical “FRUTA” e eixo horizontal “MEDIDA DE MASSA (EM QUILOGRAMAS)”. No eixo “FRUTA” é composto pelas frutas “PÊSSEGO”, “LARANJA”, “MELANCIA”, “MAÇÃ” e BANANA. A barra em frente de cada fruta será dividida em 10 quadrados iguais, conforme a referência. Pode usar como base a gt3032_1npm_g23_mdn_aj, adaptando de acordo com a descrição acima. Deixar as barras em branco para o aluno pintar. | Q37: 30 | R37: 45755 | S37: 45756 | V37: 45756 | W37: km | X37: =IF(Tabela2[[#This Row],[sigla]]="","",VLOOKUP(Tabela2[[#This Row],[sigla]],créditos_base!B:C,2,0)) -> KEITHY MOSTACHI/ARQUIVO DA EDITORA | Y37: Arte | Z37: =Tabela2[[#This Row],[ilustrador]] -> KEITHY MOSTACHI/ARQUIVO DA EDITORA | AA37: 12 | AB37: padrão | AC37: FINALIZADO | AD37: ="Pitanguá" -> Pitanguá | AE37: ="Matemática" -> Matemática
A38: g0728_1p011m_g27_e001 | B38: PRONTA | C38: GRÁFICO | D38: MIOLO | E38: 118 | F38: 1 | G38: 4 | I38: NOVA | O38: Ilustração de um gráfico de barras (vertical) no padrão da obra que apresente os dados do quadro a seguir. Fazer com base no gt1228_1npm_m20_mdn_re, adaptando conforme a referência a seguir. Ver se é preciso aproximar as barras. O eixo vertical, pode ficar até o 7. SABOR MEDIDA DA CAPACIDADE (EM LITROS) LARANJA 4 UVA 5 ACEROLA 2 MARACUJÁ 2 | Q38: 30 | R38: 45755 | S38: 45756 | V38: 45756 | W38: km | X38: =IF(Tabela2[[#This Row],[sigla]]="","",VLOOKUP(Tabela2[[#This Row],[sigla]],créditos_base!B:C,2,0)) -> KEITHY MOSTACHI/ARQUIVO DA EDITORA | Y38: Arte | Z38: =Tabela2[[#This Row],[ilustrador]] -> KEITHY MOSTACHI/ARQUIVO DA EDITORA | AA38: 12 | AB38: padrão | AC38: FINALIZADO | AD38: ="Pitanguá" -> Pitanguá | AE38: ="Matemática" -> Matemática
A39: g0728_3p011m_g27_e001 | B39: APLICADA | C39: GRÁFICO | D39: MIOLO | E39: 77 | F39: 3 | G39: 4 | I39: AJUSTE | O39: Resgatar e ajustar gráfico de quantidade de livros vendidos. Veio de: g23_mdn_lt_3npm_p077.Ccódigo antigo: gt1037zz_3npm_g23_mdn_aj AJUSTE: compor fio contorno preto do padrão da obra em torno das barras do gráfico. | Q39: 81 | R39: 45824 | V39: 45824 | W39: sl | X39: =IF(Tabela2[[#This Row],[sigla]]="","",VLOOKUP(Tabela2[[#This Row],[sigla]],créditos_base!B:C,2,0)) -> SERGIO LIMA/ARQUIVO DA EDITORA | Y39: Rebecca Baniski | Z39: =Tabela2[[#This Row],[ilustrador]] -> SERGIO LIMA/ARQUIVO DA EDITORA | AA39: 13 | AB39: resgate ajuste | AC39: FINALIZADO | AD39: ="Pitanguá" -> Pitanguá | AE39: ="Matemática" -> Matemática
A40: g0731_3p011m_g27_e001 | B40: APLICADA | C40: GRÁFICO | D40: MIOLO | E40: 193 | F40: 3 | G40: 4 | I40: AJUSTE | O40: Resgatar gráfico/ilustração quantidade de estudantes; g23_mdn_lt_3npm_p193; código antigo gt1806_3pmm_g19_mdn AJUSTE: retirar barras em cor resposta | Q40: 26 | R40: 45751 | S40: 45751 | V40: 45751 | W40: sl | X40: =IF(Tabela2[[#This Row],[sigla]]="","",VLOOKUP(Tabela2[[#This Row],[sigla]],créditos_base!B:C,2,0)) -> SERGIO LIMA/ARQUIVO DA EDITORA | Y40: Rafaela Panissa | Z40: =Tabela2[[#This Row],[ilustrador]] -> SERGIO LIMA/ARQUIVO DA EDITORA | AA40: 14 | AB40: resgate ajuste | AC40: FINALIZADO | AD40: ="Pitanguá" -> Pitanguá | AE40: ="Matemática" -> Matemática
...

Sheet créditos_base
A1: CRÉDITOS GERAIS DA MODERNA PARA REFERÊNCIA - EF1
A2: Nome do ilustrador | B2: Sigla Arte | C2: Crédito
A3: Nome do ilustrador | B3: Sigla Arte | C3: Crédito
A4: Acervo da editora | B4: xx | C4: ARQUIVO DA EDITORA
A5: Sigla ZZ (ver documento de ils. técnicas) | B5: zz | C5: VER DOCUMENTO DE ILS. TÉCNICAS
A6: ILUSTRAÇOES DE PROVAS OFICIAIS (somente se não houver crédito) | B6: yv | C6: NOME DA UNIVERSIDADE/ANO - UNICAMP 2024 NOME DO ILUSTRADOR (AJUSTE)/ARQUIVO DA EDITORA/UNIVERSIDADE ANO
A7: ILUSTRAÇÕES DE PLACAS DE TRÂNSITO | B7: yy | C7: NOME DO ILUSTRADOR/ARQUIVO DA EDITORA
A8: ILUSTRAÇÕES DE BANDEIRAS DE PAÍS | B8: yp | C8: NOME DO ILUSTRADOR/ARQUIVO DA EDITORA
A9: ILUSTRAÇÕES DE BANDEIRAS DE ESTADO | B9: ye | C9: NOME DO ILUSTRADOR/ARQUIVO DA EDITORA
A10: ILUSTRAÇÕES GERADAS POR PROGRAMAS C/ IA | B10: ia | C10: ARQUIVO DA EDITORA
A11: Arte | B11: a | C11: ARTE
A12: 3 Pixel Studio | B12: px | C12: ROBSON OLIVIERIA/ARQUIVO DA EDITORA
A13: A7 Estudio | B13: ao | C13: JORGE RIBEIRO/ARQUIVO DA EDITORA
... A41: Beatriz Mayumi | B41: bm | C41: BEATRIZ MAYUMI/ARQUIVO DA EDITORA
A42: Belli Studio Design | B42: bl
A43: Bernardo França | B43: be | C43: BERNARDO FRANÇA/ARQUIVO DA EDITORA
A44: Bianca Nazari | B44: bi | C44: BIANCA NAZARI/ARQUIVO DA EDITORA
A45: Brenda Bossato | B45: bd | C45: BRENDA BOSSATO/ARQUIVO DA EDITORA
A46: Brenda Goes | B46: bg | C46: BRENDA GOES/ARQUIVO DA EDITORA
A47: Bruna Campos | B47: bp | C47: BRUNA CAMPOS/ARQUIVO DA EDITORA
A48: Brunna Mancuso | B48: bs | C48: BRUNNA MANCUSO/ARQUIVO DA EDITORA
A49: Bruna Menezes | B49: bz | C49: BRUNA MENEZES/ARQUIVO DA EDITORA
A50: Bruno Badain | B50: bb | C50: BRUNO BADAIN/ARQUIVO DA EDITORA
A51: Bruno H. S. Cerkuenik | B51: bc | C51: BRUNO CERKUENIK/ARQUIVO DA EDITORA
A52: Bruno Nunes Coelho | B52: bn | C52: BRUNO NUNES/ARQUIVO DA EDITORA
A53: Bruno Oliveira Sampaio | B53: br | C53: BRUNO SAMPAIO/ARQUIVO DA EDITORA
A54: Bruno Rosal de Vasconcelos | B54: bu
A55: Caio Hideki Takaso Tanaka | B55: ct | C55: CAIO TANAKA/ARQUIVO DA EDITORA
A56: Camila Cristiane Pereira dos Santos | B56: cd
A57: Camila Ferreira Carmona | B57: ca | C57: CAMILA CARMONA/ARQUIVO DA EDITORA
A58: Carlitos Pinheiro | B58: cq | C58: CARLITOS PINHEIRO/ARQUIVO DA EDITORA
A59: Carlos Alberto Borin Junior | B59: cj | C59: CARLOS BORIN/ARQUIVO DA EDITORA
A60: Carlos Eduardo Nascimento | B60: cn | C60: CARLOS EDUARDO NASCIMENTO/ARQUIVO DA EDITORA
A61: Carmen Ferreira Martinez | B61: cc | C61: CARMEN MARTINEZ/ARQUIVO DA EDITORA
A62: Carol Rempto | B62: cw | C62: CAROL REMPTO/ARQUIVO DA EDITORA
A63: Carol Sartori | B63: cx | C63: CAROL SARTORI/ARQUIVO DA EDITORA
A64: Carolina Coroa | B64: kk | C64: CAROLINA COROA/ARQUIVO DA EDITORA
A65: Caroline Romão Bezerra | B65: co | C65: CAROLINE ROMÃO BEZERRA/ARQUIVO DA EDITORA
A66: Cartoon Pro | B66: cp
A67: Cássio Bittencourt | B67: cs | C67: CÁSSIO BITTENCOURT/ARQUIVO DA EDITORA
...

Sheet metadados
A1: PRÉ-EDIÇÃO | B1: ILUSTRAÇÃO | C1: CAPA | D1: 1 | E1: AJUSTE | F1: SCRIBA | G1: 1 | H1: PREVISAO
A2: EDICAO_EQUIPE | B2: IL TEC ARTE | C2: APRESENT. | D2: 2 | E2: NOVA | F2: FTD | G2: 2 | H2: FINALIZADO
A3: EDICAO_ARTE | B3: IL + FOTO | C3: SUMÁRIO | D3: 3 | E3: RESGATE | F3: MDN | G3: 3 | H3: FINALIZADO RAFE
A4: ILUSTRANDO | B4: MAPA | C4: ABERTURA | D4: 4 | F4: SABER | G4: 4 | H4: PAGO
A5: AVALIANDO | B5: GRÁFICO | C5: MIOLO | D5: 5 | F5: SM | G5: 5 | H5: PAGO RAFE
A6: AJUSTANDO | B6: LINHA TEMPO | C6: PAG.ESPECIAL | D6: 6 | F6: SCP | G6: 6
A7: FINALIZANDO | B7: INFOGRÁFICO | C7: MP-G | D7: ÚNICO | F7: ABR | G7: 7
A8: PRONTA | C8: MP-E | F8: BASE | G8: 8
A9: APLICADA | F9: IBEP | G9: 9
A10: EXCLUIDA | F10: LEYA | G10: 10
F11: SARAIVA | G11: 11
F12: SANTILLANA | G12: 12
F13: QUINTETO | G13: 13
G14: 14
